<sdf version='1.7'>
  <world name='default'>
    <physics name='default_physics' default='0' type='ode'>
      <max_step_size>0.001</max_step_size>
      <real_time_factor>1</real_time_factor>
      <real_time_update_rate>1000</real_time_update_rate>
    </physics>
    <light name='sun' type='directional'>
      <cast_shadows>1</cast_shadows>
      <pose>0 0 10 0 -0 0</pose>
      <diffuse>0.8 0.8 0.8 1</diffuse>
      <specular>0.2 0.2 0.2 1</specular>
      <attenuation>
        <range>1000</range>
        <constant>1</constant>
        <linear>0</linear>
        <quadratic>0</quadratic>
      </attenuation>
      <direction>-0.5 0.1 -0.9</direction>
      <spot>
        <inner_angle>0</inner_angle>
        <outer_angle>0</outer_angle>
        <falloff>0</falloff>
      </spot>
    </light>
    <model name='ground_plane'>
      <static>1</static>
      <link name='link'>
        <collision name='collision'>
          <geometry>
            <plane>
              <normal>0 0 1</normal>
              <size>100 100</size>
            </plane>
          </geometry>
          <surface>
            <contact>
              <collide_bitmask>65535</collide_bitmask>
              <ode/>
            </contact>
            <friction>
              <ode>
                <mu>100</mu>
                <mu2>50</mu2>
              </ode>
              <torsional>
                <ode/>
              </torsional>
            </friction>
            <bounce/>
          </surface>
          <max_contacts>10</max_contacts>
        </collision>
        <visual name='visual'>
          <cast_shadows>0</cast_shadows>
          <geometry>
            <plane>
              <normal>0 0 1</normal>
              <size>100 100</size>
            </plane>
          </geometry>
          <material>
            <script>
              <uri>file://media/materials/scripts/gazebo.material</uri>
              <name>Gazebo/Grey</name>
            </script>
          </material>
        </visual>
        <self_collide>0</self_collide>
        <kinematic>0</kinematic>
        <enable_wind>0</enable_wind>
      </link>
    </model>
    <gravity>0 0 -9.8</gravity>
    <magnetic_field>6e-06 2.3e-05 -4.2e-05</magnetic_field>
    <atmosphere type='adiabatic'/>
    <scene>
      <ambient>0.4 0.4 0.4 1</ambient>
      <background>0.7 0.7 0.7 1</background>
      <shadows>1</shadows>
    </scene>
    <spherical_coordinates>
      <surface_model>EARTH_WGS84</surface_model>
      <latitude_deg>0</latitude_deg>
      <longitude_deg>0</longitude_deg>
      <elevation>0</elevation>
      <heading_deg>0</heading_deg>
    </spherical_coordinates>
    <model name='wrc_long_table'>
      <static>1</static>
      <link name='link'>
        <inertial>
          <mass>1</mass>
        </inertial>
        <collision name='top'>
          <pose>0 0 0.39 0 -0 0</pose>
          <geometry>
            <box>
              <size>1.2 0.4 0.02</size>
            </box>
          </geometry>
          <max_contacts>10</max_contacts>
          <surface>
            <contact>
              <ode/>
            </contact>
            <bounce/>
            <friction>
              <torsional>
                <ode/>
              </torsional>
              <ode/>
            </friction>
          </surface>
        </collision>
        <visual name='top_v'>
          <pose>0 0 0.39 0 -0 0</pose>
          <geometry>
            <box>
              <size>1.2 0.4 0.02</size>
            </box>
          </geometry>
          <material>
            <script>
              <uri>file://media/materials/scripts/gazebo.material</uri>
              <name>Gazebo/White</name>
            </script>
          </material>
        </visual>
        <collision name='leg1'>
          <pose>0.59 0.19 0.185 0 -0 0</pose>
          <geometry>
            <box>
              <size>0.02 0.02 0.4</size>
            </box>
          </geometry>
          <max_contacts>10</max_contacts>
          <surface>
            <contact>
              <ode/>
            </contact>
            <bounce/>
            <friction>
              <torsional>
                <ode/>
              </torsional>
              <ode/>
            </friction>
          </surface>
        </collision>
        <visual name='leg1_v'>
          <pose>0.59 0.19 0.185 0 -0 0</pose>
          <geometry>
            <box>
              <size>0.02 0.02 0.4</size>
            </box>
          </geometry>
          <material>
            <script>
              <uri>file://media/materials/scripts/gazebo.material</uri>
              <name>Gazebo/Gray</name>
            </script>
          </material>
        </visual>
        <collision name='leg2'>
          <pose>-0.59 0.19 0.185 0 -0 0</pose>
          <geometry>
            <box>
              <size>0.02 0.02 0.4</size>
            </box>
          </geometry>
          <max_contacts>10</max_contacts>
          <surface>
            <contact>
              <ode/>
            </contact>
            <bounce/>
            <friction>
              <torsional>
                <ode/>
              </torsional>
              <ode/>
            </friction>
          </surface>
        </collision>
        <visual name='leg2_v'>
          <pose>-0.59 0.19 0.185 0 -0 0</pose>
          <geometry>
            <box>
              <size>0.02 0.02 0.4</size>
            </box>
          </geometry>
          <material>
            <script>
              <uri>file://media/materials/scripts/gazebo.material</uri>
              <name>Gazebo/Gray</name>
            </script>
          </material>
        </visual>
        <collision name='leg3'>
          <pose>0.59 -0.19 0.185 0 -0 0</pose>
          <geometry>
            <box>
              <size>0.02 0.02 0.4</size>
            </box>
          </geometry>
          <max_contacts>10</max_contacts>
          <surface>
            <contact>
              <ode/>
            </contact>
            <bounce/>
            <friction>
              <torsional>
                <ode/>
              </torsional>
              <ode/>
            </friction>
          </surface>
        </collision>
        <visual name='leg3_v'>
          <pose>0.59 -0.19 0.185 0 -0 0</pose>
          <geometry>
            <box>
              <size>0.02 0.02 0.4</size>
            </box>
          </geometry>
          <material>
            <script>
              <uri>file://media/materials/scripts/gazebo.material</uri>
              <name>Gazebo/Gray</name>
            </script>
          </material>
        </visual>
        <collision name='leg4'>
          <pose>-0.59 -0.19 0.185 0 -0 0</pose>
          <geometry>
            <box>
              <size>0.02 0.02 0.4</size>
            </box>
          </geometry>
          <max_contacts>10</max_contacts>
          <surface>
            <contact>
              <ode/>
            </contact>
            <bounce/>
            <friction>
              <torsional>
                <ode/>
              </torsional>
              <ode/>
            </friction>
          </surface>
        </collision>
        <visual name='leg4_v'>
          <pose>-0.59 -0.19 0.185 0 -0 0</pose>
          <geometry>
            <box>
              <size>0.02 0.02 0.4</size>
            </box>
          </geometry>
          <material>
            <script>
              <uri>file://media/materials/scripts/gazebo.material</uri>
              <name>Gazebo/Gray</name>
            </script>
          </material>
        </visual>
        <collision name='side_panel1'>
          <pose>0.575 0 0.32 0 -0 0</pose>
          <geometry>
            <box>
              <size>0.01 0.4 0.04</size>
            </box>
          </geometry>
          <max_contacts>10</max_contacts>
          <surface>
            <contact>
              <ode/>
            </contact>
            <bounce/>
            <friction>
              <torsional>
                <ode/>
              </torsional>
              <ode/>
            </friction>
          </surface>
        </collision>
        <visual name='side_panel1_v'>
          <pose>0.575 0 0.32 0 -0 0</pose>
          <geometry>
            <box>
              <size>0.01 0.4 0.04</size>
            </box>
          </geometry>
          <material>
            <script>
              <uri>file://media/materials/scripts/gazebo.material</uri>
              <name>Gazebo/Gray</name>
            </script>
          </material>
        </visual>
        <collision name='side_panel2'>
          <pose>-0.575 0 0.32 0 -0 0</pose>
          <geometry>
            <box>
              <size>0.01 0.4 0.04</size>
            </box>
          </geometry>
          <max_contacts>10</max_contacts>
          <surface>
            <contact>
              <ode/>
            </contact>
            <bounce/>
            <friction>
              <torsional>
                <ode/>
              </torsional>
              <ode/>
            </friction>
          </surface>
        </collision>
        <visual name='side_panel2_v'>
          <pose>-0.575 0 0.32 0 -0 0</pose>
          <geometry>
            <box>
              <size>0.01 0.4 0.04</size>
            </box>
          </geometry>
          <material>
            <script>
              <uri>file://media/materials/scripts/gazebo.material</uri>
              <name>Gazebo/Gray</name>
            </script>
          </material>
        </visual>
        <collision name='bar1'>
          <pose>0 0.2 0.29 0 1.57 0</pose>
          <geometry>
            <cylinder>
              <radius>0.01</radius>
              <length>1.16</length>
            </cylinder>
          </geometry>
          <max_contacts>10</max_contacts>
          <surface>
            <contact>
              <ode/>
            </contact>
            <bounce/>
            <friction>
              <torsional>
                <ode/>
              </torsional>
              <ode/>
            </friction>
          </surface>
        </collision>
        <visual name='bar1_v'>
          <pose>0 0.19 0.29 0 1.57 0</pose>
          <geometry>
            <cylinder>
              <radius>0.01</radius>
              <length>1.16</length>
            </cylinder>
          </geometry>
          <material>
            <script>
              <uri>file://media/materials/scripts/gazebo.material</uri>
              <name>Gazebo/Gray</name>
            </script>
          </material>
        </visual>
        <collision name='bar2'>
          <pose>0 0.08 0.29 0 1.57 0</pose>
          <geometry>
            <cylinder>
              <radius>0.01</radius>
              <length>1.16</length>
            </cylinder>
          </geometry>
          <max_contacts>10</max_contacts>
          <surface>
            <contact>
              <ode/>
            </contact>
            <bounce/>
            <friction>
              <torsional>
                <ode/>
              </torsional>
              <ode/>
            </friction>
          </surface>
        </collision>
        <visual name='bar2_v'>
          <pose>0 0.08 0.29 0 1.57 0</pose>
          <geometry>
            <cylinder>
              <radius>0.01</radius>
              <length>1.16</length>
            </cylinder>
          </geometry>
          <material>
            <script>
              <uri>file://media/materials/scripts/gazebo.material</uri>
              <name>Gazebo/Gray</name>
            </script>
          </material>
        </visual>
        <collision name='bar3'>
          <pose>0 0 0.29 0 1.57 0</pose>
          <geometry>
            <cylinder>
              <radius>0.01</radius>
              <length>1.16</length>
            </cylinder>
          </geometry>
          <max_contacts>10</max_contacts>
          <surface>
            <contact>
              <ode/>
            </contact>
            <bounce/>
            <friction>
              <torsional>
                <ode/>
              </torsional>
              <ode/>
            </friction>
          </surface>
        </collision>
        <visual name='bar3_v'>
          <pose>0 0 0.29 0 1.57 0</pose>
          <geometry>
            <cylinder>
              <radius>0.01</radius>
              <length>1.16</length>
            </cylinder>
          </geometry>
          <material>
            <script>
              <uri>file://media/materials/scripts/gazebo.material</uri>
              <name>Gazebo/Gray</name>
            </script>
          </material>
        </visual>
        <collision name='bar4'>
          <pose>0 -0.08 0.29 0 1.57 0</pose>
          <geometry>
            <cylinder>
              <radius>0.01</radius>
              <length>1.16</length>
            </cylinder>
          </geometry>
          <max_contacts>10</max_contacts>
          <surface>
            <contact>
              <ode/>
            </contact>
            <bounce/>
            <friction>
              <torsional>
                <ode/>
              </torsional>
              <ode/>
            </friction>
          </surface>
        </collision>
        <visual name='bar4_v'>
          <pose>0 -0.09 0.29 0 1.57 0</pose>
          <geometry>
            <cylinder>
              <radius>0.01</radius>
              <length>1.16</length>
            </cylinder>
          </geometry>
          <material>
            <script>
              <uri>file://media/materials/scripts/gazebo.material</uri>
              <name>Gazebo/Gray</name>
            </script>
          </material>
        </visual>
        <collision name='bar5'>
          <pose>0 -0.18 0.29 0 1.57 0</pose>
          <geometry>
            <cylinder>
              <radius>0.01</radius>
              <length>1.16</length>
            </cylinder>
          </geometry>
          <max_contacts>10</max_contacts>
          <surface>
            <contact>
              <ode/>
            </contact>
            <bounce/>
            <friction>
              <torsional>
                <ode/>
              </torsional>
              <ode/>
            </friction>
          </surface>
        </collision>
        <visual name='bar5_v'>
          <pose>0 -0.18 0.29 0 1.57 0</pose>
          <geometry>
            <cylinder>
              <radius>0.01</radius>
              <length>1.16</length>
            </cylinder>
          </geometry>
          <material>
            <script>
              <uri>file://media/materials/scripts/gazebo.material</uri>
              <name>Gazebo/Gray</name>
            </script>
          </material>
        </visual>
        <self_collide>0</self_collide>
        <kinematic>0</kinematic>
        <enable_wind>0</enable_wind>
      </link>
      <pose>1.89935 -0.053399 0 0 -0 0</pose>
    </model>
    <state world_name='default'>
      <sim_time>2178 619000000</sim_time>
      <real_time>1021 908811315</real_time>
      <wall_time>1700736957 829016900</wall_time>
      <iterations>926813</iterations>
      <model name='Banana for Scale'>
        <pose>1.03204 0.138558 0.467453 3.14159 -1.55158 3.14159</pose>
        <scale>1 1 1</scale>
        <link name='link'>
          <pose>1.03204 0.138558 0.467453 3.14159 -1.55158 3.14159</pose>
          <velocity>0 0 0 0 -0 0</velocity>
          <acceleration>0 0 0 0 -0 0</acceleration>
          <wrench>0 0 0 0 -0 0</wrench>
        </link>
      </model>
      <model name='beer'>
        <pose>0.897031 -0.346322 0.47922 -0.058414 0.000853 0.005135</pose>
        <scale>1 1 1</scale>
        <link name='link'>
          <pose>0.897095 -0.339608 0.594024 -0.058414 0.000853 0.005135</pose>
          <velocity>0 0 0 0 -0 0</velocity>
          <acceleration>-0.002978 0.022818 19.8597 -1.4889 -0.622284 -0.976811</acceleration>
          <wrench>-0.001161 0.008899 7.74528 0 -0 0</wrench>
        </link>
      </model>
      <model name='bowl'>
        <pose>0.853869 0.312438 0.440707 -0.058425 0.000659 0.000644</pose>
        <scale>1 1 1</scale>
        <link name='link'>
          <pose>0.853869 0.312438 0.440707 -0.058425 0.000659 0.000644</pose>
          <velocity>0 0 0 0 -0 0</velocity>
          <acceleration>0 0 -9.8 0 -0 0</acceleration>
          <wrench>0 0 -0.98 0 -0 0</wrench>
        </link>
      </model>
      <model name='coke_can'>
        <pose>0.883605 -0.211336 0.468373 -0.059389 -0.036059 0.002565</pose>
        <scale>1 1 1</scale>
        <link name='link'>
          <pose>0.883605 -0.211336 0.468373 -0.059389 -0.036059 0.002565</pose>
          <velocity>0 0 0 0 -0 0</velocity>
          <acceleration>6e-06 -2e-05 -1e-06 0.000351 0.0001 -2e-06</acceleration>
          <wrench>2e-06 -8e-06 -1e-06 0 -0 0</wrench>
        </link>
      </model>
      <model name='ground_plane'>
        <pose>0 0 0 0 -0 0</pose>
        <scale>1 1 1</scale>
        <link name='link'>
          <pose>0 0 0 0 -0 0</pose>
          <velocity>0 0 0 0 -0 0</velocity>
          <acceleration>0 0 0 0 -0 0</acceleration>
          <wrench>0 0 0 0 -0 0</wrench>
        </link>
      </model>
      <model name='orange'>
        <pose>0.977165 -0.067444 0.461355 -0.340941 0.145196 -2.76514</pose>
        <scale>1 1 1</scale>
        <link name='link'>
          <pose>0.977165 -0.067444 0.461355 -0.340941 0.145196 -2.76514</pose>
          <velocity>0 0 0 0 -0 0</velocity>
          <acceleration>0 0 -9.8 0 -0 0</acceleration>
          <wrench>0 0 -0.001987 0 -0 0</wrench>
        </link>
      </model>
      <model name='plastic_cup'>
        <pose>0.838097 0.002538 0.477743 1.52694 0.12224 -2.1307</pose>
        <scale>1 1 1</scale>
        <link name='link'>
          <pose>0.782891 0.036732 0.480572 1.52694 0.12224 -2.1307</pose>
          <velocity>0 0 0 0 -0 0</velocity>
          <acceleration>-3e-06 -4e-06 -2e-06 0.001708 -0.00106 -7.7e-05</acceleration>
          <wrench>-0 -0 -0 0 -0 0</wrench>
        </link>
      </model>
      <model name='tiago'>
        <pose>0.058026 -0.000311 -0.00074 0.00024 0.000285 -0.007096</pose>
        <scale>1 1 1</scale>
        <link name='arm_1_link'>
          <pose>0.151424 0.012814 0.884854 -0.000306 0.000259 -1.3779</pose>
          <velocity>-3e-06 0 -0 -4e-06 2e-06 -4e-06</velocity>
          <acceleration>-0.000324 1e-05 0.000128 0.828798 1.48986 2.61263</acceleration>
          <wrench>-0.000506 1.6e-05 0.0002 0 -0 0</wrench>
        </link>
        <link name='arm_2_link'>
          <pose>0.194517 -0.106121 0.853818 1.56947 1.33781 -1.3792</pose>
          <velocity>-3e-06 -0 1e-06 -2e-06 3e-06 -4e-06</velocity>
          <acceleration>-0.000821 -0.000292 0.00022 0.630111 -0.401562 1.21294</acceleration>
          <wrench>-0.001478 -0.000527 0.000396 0 -0 0</wrench>
        </link>
        <link name='arm_3_link'>
          <pose>0.199925 -0.126119 0.766736 0.046688 -0.228342 -1.58273</pose>
          <velocity>-4e-06 -0 1e-06 -1e-06 -5e-06 -3.3e-05</velocity>
          <acceleration>-0.002483 0.000116 0.000102 0.785456 0.227835 -0.890606</acceleration>
          <wrench>-0.004469 0.000209 0.000184 0 -0 0</wrench>
        </link>
        <link name='arm_4_link'>
          <pose>0.182947 -0.156921 0.544979 -1.52495 0.127899 -1.5663</pose>
          <velocity>-3e-06 0 1e-06 4e-06 -9e-06 -3.3e-05</velocity>
          <acceleration>0.006117 0.000448 0.0003 1.95683 0.731564 -0.842657</acceleration>
          <wrench>0.008764 0.000641 0.00043 0 -0 0</wrench>
        </link>
        <link name='arm_5_link'>
          <pose>0.210102 0.00627 0.547054 0.3391 -1.43513 -1.90832</pose>
          <velocity>2e-06 -1e-06 1e-06 3e-06 -0.000122 -4.4e-05</velocity>
          <acceleration>0.00475 -0.000222 0.000407 -2.69476 0.02935 -3.09342</acceleration>
          <wrench>0.004445 -0.000208 0.000381 0 -0 0</wrench>
        </link>
        <link name='arm_6_link'>
          <pose>0.209434 0.155044 0.566186 1.02164 -1.48456 2.11698</pose>
          <velocity>7e-06 -1e-06 2e-06 9e-06 -0.000361 1.5e-05</velocity>
          <acceleration>0.023451 -0.000113 0.000136 -2.05577 -1.18534 -2.22794</acceleration>
          <wrench>0.0071 -3.4e-05 4.1e-05 0 -0 0</wrench>
        </link>
        <link name='arm_7_link'>
          <pose>0.209434 0.155044 0.566186 0.045106 -0.073522 -1.57539</pose>
          <velocity>7e-06 -1e-06 2e-06 3e-06 -0.000279 0.000145</velocity>
          <acceleration>-0.08839 3.7e-05 -0.004686 -0.129584 -1.16568 0.386166</acceleration>
          <wrench>-0.070956 3e-05 -0.003762 0 -0 0</wrench>
        </link>
        <link name='base_footprint'>
          <pose>0.058026 -0.000311 -0.00074 0.00024 0.000285 -0.007096</pose>
          <velocity>-0 -0 2e-05 -1e-06 -3e-06 -6e-06</velocity>
          <acceleration>1.3e-05 -6e-06 0 -7.5e-05 0.000217 0.000221</acceleration>
          <wrench>0.000557 -0.000252 2.1e-05 0 -0 0</wrench>
        </link>
        <link name='caster_back_left_1_link'>
          <pose>-0.114729 0.102902 0.064433 0.000224 0.002869 -0.010465</pose>
          <velocity>1e-06 1e-06 6.8e-05 7e-06 0.001293 -3e-06</velocity>
          <acceleration>-4e-06 3e-06 9e-06 2.9e-05 -0.000511 0.00039</acceleration>
          <wrench>-0 0 0 0 -0 0</wrench>
        </link>
        <link name='caster_back_left_2_link'>
          <pose>-0.13076 0.103079 0.024492 1.57047 0.871417 3.13087</pose>
          <velocity>-1e-05 1e-06 9.7e-05 -1.1e-05 -0.000485 -3e-06</velocity>
          <acceleration>-1.7e-05 -0 0 7e-05 -0.000955 0.00034</acceleration>
          <wrench>-1e-06 -0 0 0 -0 0</wrench>
        </link>
        <link name='caster_back_right_1_link'>
          <pose>-0.116177 -0.101093 0.064414 0.00022 0.003663 0.001761</pose>
          <velocity>-0 1e-06 8.4e-05 -1.3e-05 0.001721 -1.8e-05</velocity>
          <acceleration>-1.3e-05 3e-06 7e-06 3.3e-05 -0.00043 0.000401</acceleration>
          <wrench>-1e-06 0 0 0 -0 0</wrench>
        </link>
        <link name='caster_back_right_2_link'>
          <pose>-0.132215 -0.101112 0.02449 1.57045 0.936589 -3.14012</pose>
          <velocity>-1.4e-05 1e-06 0.000123 -7e-06 -0.000665 -1.8e-05</velocity>
          <acceleration>-2.5e-05 -1e-06 -1e-06 7.9e-05 -0.001416 0.000362</acceleration>
          <wrench>-2e-06 -0 -0 0 -0 0</wrench>
        </link>
        <link name='caster_front_left_1_link'>
          <pose>0.228262 0.100468 0.064395 0.000214 0.004457 -0.048285</pose>
          <velocity>1e-06 -1e-06 0.0001 9.6e-05 0.002129 -0.000152</velocity>
          <acceleration>-3e-05 -3e-06 -1e-05 -1.1e-05 0.000229 -0.000353</acceleration>
          <wrench>-2e-06 -0 -1e-06 0 -0 0</wrench>
        </link>
        <link name='caster_front_left_2_link'>
          <pose>0.212236 0.101252 0.024488 1.57048 0.888895 3.09306</pose>
          <velocity>-1.6e-05 2e-06 0.000148 -4.5e-05 -0.000751 -0.000153</velocity>
          <acceleration>-2.6e-05 -0 1e-06 -3.9e-05 -0.001514 -0.000208</acceleration>
          <wrench>-2e-06 -0 0 0 -0 0</wrench>
        </link>
        <link name='caster_front_right_1_link'>
          <pose>0.226814 -0.103527 0.064376 0.00021 0.005258 -0.053058</pose>
          <velocity>0 -1e-06 0.000117 0.000128 0.002557 -0.000167</velocity>
          <acceleration>-3.9e-05 -3e-06 -1.2e-05 -2.8e-05 0.000195 -0.000406</acceleration>
          <wrench>-2e-06 -0 -1e-06 0 -0 0</wrench>
        </link>
        <link name='caster_front_right_2_link'>
          <pose>0.210785 -0.102666 0.024487 1.57046 0.957225 3.08826</pose>
          <velocity>-2e-05 3e-06 0.000174 -6e-05 -0.000936 -0.000168</velocity>
          <acceleration>-3.5e-05 0 -1e-06 -6.7e-05 -0.001978 -0.000232</acceleration>
          <wrench>-3e-06 0 -0 0 -0 0</wrench>
        </link>
        <link name='gripper_left_finger_link'>
          <pose>0.251134 0.159939 0.635249 -3.068 0.044985 3.14031</pose>
          <velocity>3.4e-05 5e-06 1.6e-05 2e-06 -0.000281 0.000146</velocity>
          <acceleration>-0.003077 0.018476 0.064418 1.59346 0.390742 -0.257792</acceleration>
          <wrench>-0.000338 0.002032 0.007085 0 -0 0</wrench>
        </link>
        <link name='gripper_right_finger_link'>
          <pose>0.161467 0.160054 0.631213 -3.068 0.044985 3.1403</pose>
          <velocity>0.000118 -8e-06 -6e-06 4e-06 -0.000295 0.00013</velocity>
          <acceleration>0.507723 -0.016021 -0.031506 2.60502 -0.466737 -2.53439</acceleration>
          <wrench>0.055839 -0.001762 -0.003465 0 -0 0</wrench>
        </link>
        <link name='head_1_link'>
          <pose>0.178317 -0.001413 1.03584 0.00024 0.000284 -0.00683</pose>
          <velocity>-3e-06 -0 0 -1e-06 -3e-06 -8e-06</velocity>
          <acceleration>0.000201 -5.1e-05 -0.000218 1.31897 0.086952 -0.775281</acceleration>
          <wrench>0.000125 -3.2e-05 -0.000136 0 -0 0</wrench>
        </link>
        <link name='head_2_link'>
          <pose>0.183345 -0.001471 1.13384 1.57104 0.001732 -0.00683</pose>
          <velocity>-3e-06 -0 0 -0 1.1e-05 -8e-06</velocity>
          <acceleration>5.9e-05 -4e-05 -9.5e-05 0.007511 -0.611756 -0.923956</acceleration>
          <wrench>5.3e-05 -3.6e-05 -8.4e-05 0 -0 0</wrench>
        </link>
        <link name='suspension_left_link'>
          <pose>0.058054 -0.000334 0.096394 0.00024 0.000285 -0.007096</pose>
          <velocity>-1e-06 -0 8.3e-05 -1e-06 -3e-06 -6e-06</velocity>
          <acceleration>-1.7e-05 -2e-06 -2e-06 3.2e-05 0.000222 -3.1e-05</acceleration>
          <wrench>-0.000174 -1.8e-05 -2.3e-05 0 -0 0</wrench>
        </link>
        <link name='suspension_right_link'>
          <pose>0.058054 -0.000334 0.096491 0.00024 0.000285 -0.007096</pose>
          <velocity>-1e-06 -0 8.3e-05 -1e-06 -3e-06 -6e-06</velocity>
          <acceleration>-1.7e-05 -2e-06 2e-06 3.1e-05 0.000222 -2.9e-05</acceleration>
          <wrench>-0.000175 -2e-05 2.2e-05 0 -0 0</wrench>
        </link>
        <link name='torso_lift_link'>
          <pose>-0.003678 -0.000122 1.0359 0.00024 0.000285 -0.007096</pose>
          <velocity>-3e-06 1e-06 -0 -1e-06 -3e-06 -6e-06</velocity>
          <acceleration>0.000152 -2.5e-05 -0.000188 -0.000517 0.000199 -0.003595</acceleration>
          <wrench>0.001056 -0.000175 -0.001302 0 -0 0</wrench>
        </link>
        <link name='wheel_left_link'>
          <pose>0.059489 0.201861 0.096443 -1.57051 0.603811 -0.006933</pose>
          <velocity>0 -0 8.3e-05 0 4e-06 -6e-06</velocity>
          <acceleration>-6e-06 -3e-06 4e-06 -4.4e-05 -0.009895 -4.6e-05</acceleration>
          <wrench>-1.2e-05 -5e-06 7e-06 0 -0 0</wrench>
        </link>
        <link name='wheel_right_link'>
          <pose>0.056619 -0.202529 0.096443 -1.57051 0.574674 -0.006943</pose>
          <velocity>-2e-06 -0 8.3e-05 0 -2e-05 -6e-06</velocity>
          <acceleration>-1.9e-05 -3e-06 -4e-06 0.000193 0.023328 -4.9e-05</acceleration>
          <wrench>-3.5e-05 -5e-06 -7e-06 0 -0 0</wrench>
        </link>
      </model>
      <model name='unit_box'>
        <pose>0.835133 -0.622388 0.067092 0.016789 0.012974 -0.009606</pose>
        <scale>0.64685 0.602268 0.097501</scale>
        <link name='link'>
          <pose>0.835133 -0.622388 0.067092 0.016789 0.012974 -0.009606</pose>
          <velocity>0 0 0 0 -0 0</velocity>
          <acceleration>-0.199803 0.371049 30.8012 2.73229 1.10203 -0.079044</acceleration>
          <wrench>-0.199803 0.371049 30.8012 0 -0 0</wrench>
        </link>
      </model>
      <model name='wrc_long_table'>
        <pose>0.871421 -0.043233 0.060821 0 0.05843 1.56133</pose>
        <scale>1 1 1</scale>
        <link name='link'>
          <pose>0.871421 -0.043233 0.060821 0 0.05843 1.56133</pose>
          <velocity>0 0 0 0 -0 0</velocity>
          <acceleration>0 0 0 0 -0 0</acceleration>
          <wrench>0 0 0 0 -0 0</wrench>
        </link>
      </model>
      <light name='sun'>
        <pose>2.52076 0.008328 10 0 -0 0</pose>
      </light>
      <light name='user_spot_light_0'>
        <pose>0.130511 -0.140534 2.73543 0 -0.497484 0</pose>
      </light>
    </state>
    <gui fullscreen='0'>
      <camera name='user_camera'>
        <pose>2.09988 3.83575 2.09703 0 0.553798 -1.64225</pose>
        <view_controller>orbit</view_controller>
        <projection_type>perspective</projection_type>
      </camera>
    </gui>
    <light name='user_spot_light_0' type='spot'>
      <pose>0.988981 0.326539 1 0 -0 0</pose>
      <diffuse>0.9 0.9 0.9 1</diffuse>
      <specular>0.1 0.1 0.1 1</specular>
      <direction>0 0 -1</direction>
      <attenuation>
        <range>200</range>
        <constant>0.2</constant>
        <linear>0.2</linear>
        <quadratic>0.001</quadratic>
      </attenuation>
      <cast_shadows>0</cast_shadows>
      <spot>
        <inner_angle>0.6</inner_angle>
        <outer_angle>1</outer_angle>
        <falloff>1</falloff>
      </spot>
    </light>
    <audio>
      <device>default</device>
    </audio>
    <wind/>
    <model name='unit_box'>
      <pose>0.80961 -1.23958 0.5 0 -0 0</pose>
      <link name='link'>
        <inertial>
          <mass>1</mass>
          <inertia>
            <ixx>0.166667</ixx>
            <ixy>0</ixy>
            <ixz>0</ixz>
            <iyy>0.166667</iyy>
            <iyz>0</iyz>
            <izz>0.166667</izz>
          </inertia>
          <pose>0 0 0 0 -0 0</pose>
        </inertial>
        <collision name='collision'>
          <geometry>
            <box>
              <size>0.999998 1 0.99999</size>
            </box>
          </geometry>
          <max_contacts>10</max_contacts>
          <surface>
            <contact>
              <ode/>
            </contact>
            <bounce/>
            <friction>
              <torsional>
                <ode/>
              </torsional>
              <ode/>
            </friction>
          </surface>
        </collision>
        <visual name='visual'>
          <geometry>
            <box>
              <size>0.999998 1 0.99999</size>
            </box>
          </geometry>
          <material>
            <script>
              <name>Gazebo/Grey</name>
              <uri>file://media/materials/scripts/gazebo.material</uri>
            </script>
          </material>
        </visual>
        <self_collide>0</self_collide>
        <enable_wind>0</enable_wind>
        <kinematic>0</kinematic>
      </link>
    </model>
    <model name='tiago'>
      <link name='base_footprint'>
        <inertial>
          <pose>-0.00978 -0.00152 0.213783 0 -0 0</pose>
          <mass>42.8506</mass>
          <inertia>
            <ixx>2.01958</ixx>
            <ixy>0.00074088</ixy>
            <ixz>0.109957</ixz>
            <iyy>2.0976</iyy>
            <iyz>0.0139293</iyz>
            <izz>0.666852</izz>
          </inertia>
        </inertial>
        <collision name='base_footprint_fixed_joint_lump__base_link_collision'>
          <pose>0 0 0.0985 0 -0 0</pose>
          <geometry>
            <mesh>
              <scale>1 1 1</scale>
              <uri>/home/jin/ros/tiago_ws/src/pmb2_robot/pmb2_description/meshes/base/base_collision.stl</uri>
            </mesh>
          </geometry>
          <surface>
            <contact>
              <ode/>
            </contact>
            <friction>
              <ode/>
              <torsional>
                <ode/>
              </torsional>
            </friction>
            <bounce/>
          </surface>
          <max_contacts>10</max_contacts>
        </collision>
        <collision name='base_footprint_fixed_joint_lump__base_antenna_left_link_collision_1'>
          <pose>-0.201 0.1062 0.3785 0 -0 0</pose>
          <geometry>
            <cylinder>
              <length>0.17</length>
              <radius>0.005</radius>
            </cylinder>
          </geometry>
          <surface>
            <contact>
              <ode/>
            </contact>
            <friction>
              <ode/>
              <torsional>
                <ode/>
              </torsional>
            </friction>
            <bounce/>
          </surface>
          <max_contacts>10</max_contacts>
        </collision>
        <collision name='base_footprint_fixed_joint_lump__base_antenna_right_link_collision_2'>
          <pose>-0.201 -0.1062 0.3785 0 -0 0</pose>
          <geometry>
            <cylinder>
              <length>0.17</length>
              <radius>0.005</radius>
            </cylinder>
          </geometry>
          <surface>
            <contact>
              <ode/>
            </contact>
            <friction>
              <ode/>
              <torsional>
                <ode/>
              </torsional>
            </friction>
            <bounce/>
          </surface>
          <max_contacts>10</max_contacts>
        </collision>
        <collision name='base_footprint_fixed_joint_lump__base_laser_link_collision_3'>
          <pose>0.202 0 0.0945 0 -0 0</pose>
          <geometry>
            <cylinder>
              <length>0.04</length>
              <radius>0.02</radius>
            </cylinder>
          </geometry>
          <surface>
            <contact>
              <ode/>
            </contact>
            <friction>
              <ode/>
              <torsional>
                <ode/>
              </torsional>
            </friction>
            <bounce/>
          </surface>
          <max_contacts>10</max_contacts>
        </collision>
        <collision name='base_footprint_fixed_joint_lump__torso_fixed_column_link_collision_4'>
          <pose>-0.062 0 0.5685 0 -0 0</pose>
          <geometry>
            <box>
              <size>0.23 0.253 0.45</size>
            </box>
          </geometry>
          <surface>
            <contact>
              <ode/>
            </contact>
            <friction>
              <ode/>
              <torsional>
                <ode/>
              </torsional>
            </friction>
            <bounce/>
          </surface>
          <max_contacts>10</max_contacts>
        </collision>
        <collision name='base_footprint_fixed_joint_lump__torso_fixed_link_collision_5'>
          <pose>0.023 0 0.3115 0 -0 0</pose>
          <geometry>
            <box>
              <size>0.4 0.265 0.05</size>
            </box>
          </geometry>
          <max_contacts>10</max_contacts>
          <surface>
            <contact>
              <ode/>
            </contact>
            <bounce/>
            <friction>
              <torsional>
                <ode/>
              </torsional>
              <ode/>
            </friction>
          </surface>
        </collision>
        <collision name='base_footprint_fixed_joint_lump__torso_fixed_link_collision_6'>
          <pose>-0.062 0 0.3415 0 -0 0</pose>
          <geometry>
            <box>
              <size>0.255 0.255 0.117</size>
            </box>
          </geometry>
          <max_contacts>10</max_contacts>
          <surface>
            <contact>
              <ode/>
            </contact>
            <bounce/>
            <friction>
              <torsional>
                <ode/>
              </torsional>
              <ode/>
            </friction>
          </surface>
        </collision>
        <visual name='base_footprint_fixed_joint_lump__base_link_visual'>
          <pose>0 0 0.0985 0 -0 0</pose>
          <geometry>
            <mesh>
              <scale>1 1 1</scale>
              <uri>/home/jin/ros/tiago_ws/src/pmb2_robot/pmb2_description/meshes/base/base.stl</uri>
            </mesh>
          </geometry>
          <material>
            <script>
              <name>Gazebo/White</name>
              <uri>file://media/materials/scripts/gazebo.material</uri>
            </script>
          </material>
        </visual>
        <visual name='base_footprint_fixed_joint_lump__base_antenna_left_link_visual_1'>
          <pose>-0.201 0.1062 0.2935 0 -0 0</pose>
          <geometry>
            <mesh>
              <scale>1 1 1</scale>
              <uri>/home/jin/ros/tiago_ws/src/pmb2_robot/pmb2_description/meshes/objects/antenna.stl</uri>
            </mesh>
          </geometry>
          <material>
            <script>
              <name>Gazebo/Black</name>
              <uri>file://media/materials/scripts/gazebo.material</uri>
            </script>
          </material>
        </visual>
        <visual name='base_footprint_fixed_joint_lump__base_antenna_right_link_visual_2'>
          <pose>-0.201 -0.1062 0.2935 0 -0 0</pose>
          <geometry>
            <mesh>
              <scale>1 1 1</scale>
              <uri>/home/jin/ros/tiago_ws/src/pmb2_robot/pmb2_description/meshes/objects/antenna.stl</uri>
            </mesh>
          </geometry>
          <material>
            <script>
              <name>Gazebo/Black</name>
              <uri>file://media/materials/scripts/gazebo.material</uri>
            </script>
          </material>
        </visual>
        <visual name='base_footprint_fixed_joint_lump__base_laser_link_visual_3'>
          <pose>0.202 0 0.0945 0 -0 0</pose>
          <geometry>
            <mesh>
              <scale>1 1 1</scale>
              <uri>/home/jin/ros/tiago_ws/src/pmb2_robot/pmb2_description/meshes/sensors/sick_tim551.stl</uri>
            </mesh>
          </geometry>
          <material>
            <script>
              <name>Gazebo/DarkGrey</name>
              <uri>file://media/materials/scripts/gazebo.material</uri>
            </script>
          </material>
        </visual>
        <visual name='base_footprint_fixed_joint_lump__base_sonar_01_link_visual_4'>
          <pose>-0.183 -0.183 0.2715 0 0 -2.35619</pose>
          <geometry>
            <mesh>
              <scale>1 1 1</scale>
              <uri>/home/jin/ros/tiago_ws/src/pmb2_robot/pmb2_description/meshes/sensors/srf05.stl</uri>
            </mesh>
          </geometry>
          <material>
            <script>
              <name>Gazebo/DarkGrey</name>
              <uri>file://media/materials/scripts/gazebo.material</uri>
            </script>
          </material>
        </visual>
        <visual name='base_footprint_fixed_joint_lump__base_sonar_02_link_visual_5'>
          <pose>-0.259 0 0.2715 0 -0 3.14159</pose>
          <geometry>
            <mesh>
              <scale>1 1 1</scale>
              <uri>/home/jin/ros/tiago_ws/src/pmb2_robot/pmb2_description/meshes/sensors/srf05.stl</uri>
            </mesh>
          </geometry>
          <material>
            <script>
              <name>Gazebo/DarkGrey</name>
              <uri>file://media/materials/scripts/gazebo.material</uri>
            </script>
          </material>
        </visual>
        <visual name='base_footprint_fixed_joint_lump__base_sonar_03_link_visual_6'>
          <pose>-0.183 0.183 0.2715 0 -0 2.35619</pose>
          <geometry>
            <mesh>
              <scale>1 1 1</scale>
              <uri>/home/jin/ros/tiago_ws/src/pmb2_robot/pmb2_description/meshes/sensors/srf05.stl</uri>
            </mesh>
          </geometry>
          <material>
            <script>
              <name>Gazebo/DarkGrey</name>
              <uri>file://media/materials/scripts/gazebo.material</uri>
            </script>
          </material>
        </visual>
        <visual name='base_footprint_fixed_joint_lump__torso_fixed_column_link_visual_7'>
          <pose>-0.062 0 0.5685 0 -0 0</pose>
          <geometry>
            <box>
              <size>0.18 0.2 0.55</size>
            </box>
          </geometry>
          <material>
            <script>
              <name>Gazebo/DarkGrey</name>
              <uri>file://media/materials/scripts/gazebo.material</uri>
            </script>
          </material>
        </visual>
        <visual name='base_footprint_fixed_joint_lump__torso_fixed_link_visual_8'>
          <pose>-0.062 0 0.2915 0 -0 0</pose>
          <geometry>
            <mesh>
              <scale>1 1 1</scale>
              <uri>/home/jin/ros/tiago_ws/src/tiago_robot/tiago_description/meshes/torso/torso_fix.stl</uri>
            </mesh>
          </geometry>
        </visual>
        <visual name='base_footprint_fixed_joint_lump__base_cover_link_visual_9'>
          <pose>0 0 0.13 0 -0 0</pose>
          <geometry>
            <mesh>
              <scale>1 1 1</scale>
              <uri>/home/jin/ros/tiago_ws/src/pmb2_robot/pmb2_description/meshes/base/base_ring.stl</uri>
            </mesh>
          </geometry>
          <material>
            <script>
              <name>Gazebo/Orange</name>
              <uri>file://media/materials/scripts/gazebo.material</uri>
            </script>
          </material>
        </visual>
        <sensor name='imu_sensor' type='imu'>
          <always_on>1</always_on>
          <update_rate>1000</update_rate>
          <imu>
            <noise>
              <type>gaussian</type>
              <rate>
                <mean>0.0</mean>
                <stddev>2e-4</stddev>
                <bias_mean>0.0000075</bias_mean>
                <bias_stddev>0.0000008</bias_stddev>
              </rate>
              <accel>
                <mean>0.0</mean>
                <stddev>1.7e-2</stddev>
                <bias_mean>0.1</bias_mean>
                <bias_stddev>0.001</bias_stddev>
              </accel>
            </noise>
          </imu>
          <pose>0.10171 0 0.21132 0 0 -1.5708</pose>
        </sensor>
        <sensor name='base_imu_sensor' type='imu'>
          <always_on>1</always_on>
          <update_rate>100</update_rate>
          <imu>
            <noise>
              <type>gaussian</type>
              <rate>
                <mean>0.0</mean>
                <stddev>2e-4</stddev>
                <bias_mean>0.0000075</bias_mean>
                <bias_stddev>0.0000008</bias_stddev>
              </rate>
              <accel>
                <mean>0.0</mean>
                <stddev>1.7e-2</stddev>
                <bias_mean>0.1</bias_mean>
                <bias_stddev>0.001</bias_stddev>
              </accel>
            </noise>
          </imu>
          <pose>0.10171 0 0.21132 0 0 -1.5708</pose>
        </sensor>
        <sensor name='base_laser' type='gpu_ray'>
          <update_rate>10</update_rate>
          <visualize>1</visualize>
          <ray>
            <scan>
              <horizontal>
                <samples>666</samples>
                <resolution>1</resolution>
                <min_angle>-1.91986</min_angle>
                <max_angle>1.91986</max_angle>
              </horizontal>
              <vertical>
                <samples>1</samples>
                <min_angle>0</min_angle>
                <max_angle>0</max_angle>
              </vertical>
            </scan>
            <range>
              <min>0.05</min>
              <max>25</max>
              <resolution>0.001</resolution>
            </range>
          </ray>
          <plugin name='gazebo_ros_sick_laser' filename='libgazebo_ros_gpu_laser.so'>
            <gaussianNoise>0.06</gaussianNoise>
            <alwaysOn>1</alwaysOn>
            <updateRate>10</updateRate>
            <topicName>scan_raw</topicName>
            <frameName>base_laser_link</frameName>
            <robotNamespace>/</robotNamespace>
          </plugin>
          <pose>0.202 0 0.0945 0 -0 0</pose>
        </sensor>
        <sensor name='base_sonar_01' type='ray'>
          <update_rate>5</update_rate>
          <visualize>0</visualize>
          <ray>
            <scan>
              <horizontal>
                <samples>5</samples>
                <resolution>1</resolution>
                <min_angle>-0.25</min_angle>
                <max_angle>0.25</max_angle>
              </horizontal>
              <vertical>
                <samples>5</samples>
                <resolution>1</resolution>
                <min_angle>-0.25</min_angle>
                <max_angle>0.25</max_angle>
              </vertical>
            </scan>
            <range>
              <min>0.02</min>
              <max>1</max>
              <resolution>0.01</resolution>
            </range>
          </ray>
          <plugin name='gazebo_ros_range' filename='libgazebo_ros_range.so'>
            <gaussianNoise>0.005</gaussianNoise>
            <alwaysOn>1</alwaysOn>
            <updateRate>5</updateRate>
            <topicName>sonar_base</topicName>
            <frameName>base_sonar_01_link</frameName>
            <minRange>0.02</minRange>
            <maxRange>1.0</maxRange>
            <fov>0.5</fov>
            <radiation>ultrasound</radiation>
            <robotNamespace>/</robotNamespace>
          </plugin>
          <pose>-0.183 -0.183 0.2715 0 -0 -2.35619</pose>
        </sensor>
        <sensor name='base_sonar_02' type='ray'>
          <update_rate>5</update_rate>
          <visualize>0</visualize>
          <ray>
            <scan>
              <horizontal>
                <samples>5</samples>
                <resolution>1</resolution>
                <min_angle>-0.25</min_angle>
                <max_angle>0.25</max_angle>
              </horizontal>
              <vertical>
                <samples>5</samples>
                <resolution>1</resolution>
                <min_angle>-0.25</min_angle>
                <max_angle>0.25</max_angle>
              </vertical>
            </scan>
            <range>
              <min>0.02</min>
              <max>1</max>
              <resolution>0.01</resolution>
            </range>
          </ray>
          <plugin name='gazebo_ros_range' filename='libgazebo_ros_range.so'>
            <gaussianNoise>0.005</gaussianNoise>
            <alwaysOn>1</alwaysOn>
            <updateRate>5</updateRate>
            <topicName>sonar_base</topicName>
            <frameName>base_sonar_02_link</frameName>
            <minRange>0.02</minRange>
            <maxRange>1.0</maxRange>
            <fov>0.5</fov>
            <radiation>ultrasound</radiation>
            <robotNamespace>/</robotNamespace>
          </plugin>
          <pose>-0.259 0 0.2715 0 -0 3.14159</pose>
        </sensor>
        <sensor name='base_sonar_03' type='ray'>
          <update_rate>5</update_rate>
          <visualize>0</visualize>
          <ray>
            <scan>
              <horizontal>
                <samples>5</samples>
                <resolution>1</resolution>
                <min_angle>-0.25</min_angle>
                <max_angle>0.25</max_angle>
              </horizontal>
              <vertical>
                <samples>5</samples>
                <resolution>1</resolution>
                <min_angle>-0.25</min_angle>
                <max_angle>0.25</max_angle>
              </vertical>
            </scan>
            <range>
              <min>0.02</min>
              <max>1</max>
              <resolution>0.01</resolution>
            </range>
          </ray>
          <plugin name='gazebo_ros_range' filename='libgazebo_ros_range.so'>
            <gaussianNoise>0.005</gaussianNoise>
            <alwaysOn>1</alwaysOn>
            <updateRate>5</updateRate>
            <topicName>sonar_base</topicName>
            <frameName>base_sonar_03_link</frameName>
            <minRange>0.02</minRange>
            <maxRange>1.0</maxRange>
            <fov>0.5</fov>
            <radiation>ultrasound</radiation>
            <robotNamespace>/</robotNamespace>
          </plugin>
          <pose>-0.183 0.183 0.2715 0 -0 2.35619</pose>
        </sensor>
        <self_collide>0</self_collide>
        <enable_wind>0</enable_wind>
        <kinematic>0</kinematic>
      </link>
      <joint name='caster_back_left_1_joint' type='revolute'>
        <pose relative_to='base_footprint'>-0.1735 0.102 0.065 0 -0 0</pose>
        <parent>base_footprint</parent>
        <child>caster_back_left_1_link</child>
        <axis>
          <xyz>0 0 1</xyz>
          <limit>
            <lower>-1e+16</lower>
            <upper>1e+16</upper>
          </limit>
          <dynamics>
            <damping>0.005</damping>
            <friction>0</friction>
            <spring_reference>0</spring_reference>
            <spring_stiffness>0</spring_stiffness>
          </dynamics>
        </axis>
      </joint>
      <link name='caster_back_left_1_link'>
        <pose relative_to='caster_back_left_1_joint'>0 0 0 0 -0 0</pose>
        <inertial>
          <pose>-0.006346 5.3e-05 -0.020375 0 -0 0</pose>
          <mass>0.0514476</mass>
          <inertia>
            <ixx>1.513e-05</ixx>
            <ixy>-3e-08</ixy>
            <ixz>2.67e-06</ixz>
            <iyy>1.309e-05</iyy>
            <iyz>-5e-08</iyz>
            <izz>1.198e-05</izz>
          </inertia>
        </inertial>
        <visual name='caster_back_left_1_link_visual'>
          <pose>0 0 0 0 -0 0</pose>
          <geometry>
            <mesh>
              <scale>1 1 1</scale>
              <uri>/home/jin/ros/tiago_ws/src/pmb2_robot/pmb2_description/meshes/wheels/caster_1.stl</uri>
            </mesh>
          </geometry>
          <material>
            <script>
              <name>Gazebo/DarkGrey</name>
              <uri>file://media/materials/scripts/gazebo.material</uri>
            </script>
          </material>
        </visual>
        <self_collide>0</self_collide>
        <enable_wind>0</enable_wind>
        <kinematic>0</kinematic>
      </link>
      <joint name='caster_back_left_2_joint' type='revolute'>
        <pose relative_to='caster_back_left_1_link'>-0.016 0 -0.04 -1.5708 0 0</pose>
        <parent>caster_back_left_1_link</parent>
        <child>caster_back_left_2_link</child>
        <axis>
          <xyz>0 0 1</xyz>
          <limit>
            <lower>-1e+16</lower>
            <upper>1e+16</upper>
          </limit>
          <dynamics>
            <spring_reference>0</spring_reference>
            <spring_stiffness>0</spring_stiffness>
          </dynamics>
        </axis>
      </joint>
      <link name='caster_back_left_2_link'>
        <pose relative_to='caster_back_left_2_joint'>0 0 0 0 -0 0</pose>
        <inertial>
          <pose>0 0 0 0 -0 0</pose>
          <mass>0.0885578</mass>
          <inertia>
            <ixx>1.075e-05</ixx>
            <ixy>0</ixy>
            <ixz>0</ixz>
            <iyy>1.541e-05</iyy>
            <iyz>0</iyz>
            <izz>1.075e-05</izz>
          </inertia>
        </inertial>
        <collision name='caster_back_left_2_link_collision'>
          <pose>0 0 0 0 -0 0</pose>
          <geometry>
            <sphere>
              <radius>0.025</radius>
            </sphere>
          </geometry>
          <surface>
            <contact>
              <ode>
                <kp>1e+07</kp>
                <kd>10</kd>
                <max_vel>10</max_vel>
                <min_depth>0.0005</min_depth>
              </ode>
            </contact>
            <friction>
              <ode>
                <mu>0.1</mu>
                <mu2>0.1</mu2>
              </ode>
              <torsional>
                <ode/>
              </torsional>
            </friction>
            <bounce/>
          </surface>
          <max_contacts>10</max_contacts>
        </collision>
        <visual name='caster_back_left_2_link_visual'>
          <pose>0 0 0 0 -0 0</pose>
          <geometry>
            <mesh>
              <scale>1 1 1</scale>
              <uri>/home/jin/ros/tiago_ws/src/pmb2_robot/pmb2_description/meshes/wheels/caster_2.stl</uri>
            </mesh>
          </geometry>
          <material>
            <script>
              <name>Gazebo/DarkGrey</name>
              <uri>file://media/materials/scripts/gazebo.material</uri>
            </script>
          </material>
        </visual>
        <self_collide>0</self_collide>
        <enable_wind>0</enable_wind>
        <kinematic>0</kinematic>
      </link>
      <joint name='caster_back_right_1_joint' type='revolute'>
        <pose relative_to='base_footprint'>-0.1735 -0.102 0.065 0 -0 0</pose>
        <parent>base_footprint</parent>
        <child>caster_back_right_1_link</child>
        <axis>
          <xyz>0 0 1</xyz>
          <limit>
            <lower>-1e+16</lower>
            <upper>1e+16</upper>
          </limit>
          <dynamics>
            <damping>0.005</damping>
            <friction>0</friction>
            <spring_reference>0</spring_reference>
            <spring_stiffness>0</spring_stiffness>
          </dynamics>
        </axis>
      </joint>
      <link name='caster_back_right_1_link'>
        <pose relative_to='caster_back_right_1_joint'>0 0 0 0 -0 0</pose>
        <inertial>
          <pose>-0.006346 5.3e-05 -0.020375 0 -0 0</pose>
          <mass>0.0514476</mass>
          <inertia>
            <ixx>1.513e-05</ixx>
            <ixy>-3e-08</ixy>
            <ixz>2.67e-06</ixz>
            <iyy>1.309e-05</iyy>
            <iyz>-5e-08</iyz>
            <izz>1.198e-05</izz>
          </inertia>
        </inertial>
        <visual name='caster_back_right_1_link_visual'>
          <pose>0 0 0 0 -0 0</pose>
          <geometry>
            <mesh>
              <scale>1 1 1</scale>
              <uri>/home/jin/ros/tiago_ws/src/pmb2_robot/pmb2_description/meshes/wheels/caster_1.stl</uri>
            </mesh>
          </geometry>
          <material>
            <script>
              <name>Gazebo/DarkGrey</name>
              <uri>file://media/materials/scripts/gazebo.material</uri>
            </script>
          </material>
        </visual>
        <self_collide>0</self_collide>
        <enable_wind>0</enable_wind>
        <kinematic>0</kinematic>
      </link>
      <joint name='caster_back_right_2_joint' type='revolute'>
        <pose relative_to='caster_back_right_1_link'>-0.016 0 -0.04 -1.5708 0 0</pose>
        <parent>caster_back_right_1_link</parent>
        <child>caster_back_right_2_link</child>
        <axis>
          <xyz>0 0 1</xyz>
          <limit>
            <lower>-1e+16</lower>
            <upper>1e+16</upper>
          </limit>
          <dynamics>
            <spring_reference>0</spring_reference>
            <spring_stiffness>0</spring_stiffness>
          </dynamics>
        </axis>
      </joint>
      <link name='caster_back_right_2_link'>
        <pose relative_to='caster_back_right_2_joint'>0 0 0 0 -0 0</pose>
        <inertial>
          <pose>0 0 0 0 -0 0</pose>
          <mass>0.0885578</mass>
          <inertia>
            <ixx>1.075e-05</ixx>
            <ixy>0</ixy>
            <ixz>0</ixz>
            <iyy>1.541e-05</iyy>
            <iyz>0</iyz>
            <izz>1.075e-05</izz>
          </inertia>
        </inertial>
        <collision name='caster_back_right_2_link_collision'>
          <pose>0 0 0 0 -0 0</pose>
          <geometry>
            <sphere>
              <radius>0.025</radius>
            </sphere>
          </geometry>
          <surface>
            <contact>
              <ode>
                <kp>1e+07</kp>
                <kd>10</kd>
                <max_vel>10</max_vel>
                <min_depth>0.0005</min_depth>
              </ode>
            </contact>
            <friction>
              <ode>
                <mu>0.1</mu>
                <mu2>0.1</mu2>
              </ode>
              <torsional>
                <ode/>
              </torsional>
            </friction>
            <bounce/>
          </surface>
          <max_contacts>10</max_contacts>
        </collision>
        <visual name='caster_back_right_2_link_visual'>
          <pose>0 0 0 0 -0 0</pose>
          <geometry>
            <mesh>
              <scale>1 1 1</scale>
              <uri>/home/jin/ros/tiago_ws/src/pmb2_robot/pmb2_description/meshes/wheels/caster_2.stl</uri>
            </mesh>
          </geometry>
          <material>
            <script>
              <name>Gazebo/DarkGrey</name>
              <uri>file://media/materials/scripts/gazebo.material</uri>
            </script>
          </material>
        </visual>
        <self_collide>0</self_collide>
        <enable_wind>0</enable_wind>
        <kinematic>0</kinematic>
      </link>
      <joint name='caster_front_left_1_joint' type='revolute'>
        <pose relative_to='base_footprint'>0.1695 0.102 0.065 0 -0 0</pose>
        <parent>base_footprint</parent>
        <child>caster_front_left_1_link</child>
        <axis>
          <xyz>0 0 1</xyz>
          <limit>
            <lower>-1e+16</lower>
            <upper>1e+16</upper>
          </limit>
          <dynamics>
            <damping>0.005</damping>
            <friction>0</friction>
            <spring_reference>0</spring_reference>
            <spring_stiffness>0</spring_stiffness>
          </dynamics>
        </axis>
      </joint>
      <link name='caster_front_left_1_link'>
        <pose relative_to='caster_front_left_1_joint'>0 0 0 0 -0 0</pose>
        <inertial>
          <pose>-0.006346 5.3e-05 -0.020375 0 -0 0</pose>
          <mass>0.0514476</mass>
          <inertia>
            <ixx>1.513e-05</ixx>
            <ixy>-3e-08</ixy>
            <ixz>2.67e-06</ixz>
            <iyy>1.309e-05</iyy>
            <iyz>-5e-08</iyz>
            <izz>1.198e-05</izz>
          </inertia>
        </inertial>
        <visual name='caster_front_left_1_link_visual'>
          <pose>0 0 0 0 -0 0</pose>
          <geometry>
            <mesh>
              <scale>1 1 1</scale>
              <uri>/home/jin/ros/tiago_ws/src/pmb2_robot/pmb2_description/meshes/wheels/caster_1.stl</uri>
            </mesh>
          </geometry>
          <material>
            <script>
              <name>Gazebo/DarkGrey</name>
              <uri>file://media/materials/scripts/gazebo.material</uri>
            </script>
          </material>
        </visual>
        <self_collide>0</self_collide>
        <enable_wind>0</enable_wind>
        <kinematic>0</kinematic>
      </link>
      <joint name='caster_front_left_2_joint' type='revolute'>
        <pose relative_to='caster_front_left_1_link'>-0.016 0 -0.04 -1.5708 0 0</pose>
        <parent>caster_front_left_1_link</parent>
        <child>caster_front_left_2_link</child>
        <axis>
          <xyz>0 0 1</xyz>
          <limit>
            <lower>-1e+16</lower>
            <upper>1e+16</upper>
          </limit>
          <dynamics>
            <spring_reference>0</spring_reference>
            <spring_stiffness>0</spring_stiffness>
          </dynamics>
        </axis>
      </joint>
      <link name='caster_front_left_2_link'>
        <pose relative_to='caster_front_left_2_joint'>0 0 0 0 -0 0</pose>
        <inertial>
          <pose>0 0 0 0 -0 0</pose>
          <mass>0.0885578</mass>
          <inertia>
            <ixx>1.075e-05</ixx>
            <ixy>0</ixy>
            <ixz>0</ixz>
            <iyy>1.541e-05</iyy>
            <iyz>0</iyz>
            <izz>1.075e-05</izz>
          </inertia>
        </inertial>
        <collision name='caster_front_left_2_link_collision'>
          <pose>0 0 0 0 -0 0</pose>
          <geometry>
            <sphere>
              <radius>0.025</radius>
            </sphere>
          </geometry>
          <surface>
            <contact>
              <ode>
                <kp>1e+07</kp>
                <kd>10</kd>
                <max_vel>10</max_vel>
                <min_depth>0.0005</min_depth>
              </ode>
            </contact>
            <friction>
              <ode>
                <mu>0.1</mu>
                <mu2>0.1</mu2>
              </ode>
              <torsional>
                <ode/>
              </torsional>
            </friction>
            <bounce/>
          </surface>
          <max_contacts>10</max_contacts>
        </collision>
        <visual name='caster_front_left_2_link_visual'>
          <pose>0 0 0 0 -0 0</pose>
          <geometry>
            <mesh>
              <scale>1 1 1</scale>
              <uri>/home/jin/ros/tiago_ws/src/pmb2_robot/pmb2_description/meshes/wheels/caster_2.stl</uri>
            </mesh>
          </geometry>
          <material>
            <script>
              <name>Gazebo/DarkGrey</name>
              <uri>file://media/materials/scripts/gazebo.material</uri>
            </script>
          </material>
        </visual>
        <self_collide>0</self_collide>
        <enable_wind>0</enable_wind>
        <kinematic>0</kinematic>
      </link>
      <joint name='caster_front_right_1_joint' type='revolute'>
        <pose relative_to='base_footprint'>0.1695 -0.102 0.065 0 -0 0</pose>
        <parent>base_footprint</parent>
        <child>caster_front_right_1_link</child>
        <axis>
          <xyz>0 0 1</xyz>
          <limit>
            <lower>-1e+16</lower>
            <upper>1e+16</upper>
          </limit>
          <dynamics>
            <damping>0.005</damping>
            <friction>0</friction>
            <spring_reference>0</spring_reference>
            <spring_stiffness>0</spring_stiffness>
          </dynamics>
        </axis>
      </joint>
      <link name='caster_front_right_1_link'>
        <pose relative_to='caster_front_right_1_joint'>0 0 0 0 -0 0</pose>
        <inertial>
          <pose>-0.006346 5.3e-05 -0.020375 0 -0 0</pose>
          <mass>0.0514476</mass>
          <inertia>
            <ixx>1.513e-05</ixx>
            <ixy>-3e-08</ixy>
            <ixz>2.67e-06</ixz>
            <iyy>1.309e-05</iyy>
            <iyz>-5e-08</iyz>
            <izz>1.198e-05</izz>
          </inertia>
        </inertial>
        <visual name='caster_front_right_1_link_visual'>
          <pose>0 0 0 0 -0 0</pose>
          <geometry>
            <mesh>
              <scale>1 1 1</scale>
              <uri>/home/jin/ros/tiago_ws/src/pmb2_robot/pmb2_description/meshes/wheels/caster_1.stl</uri>
            </mesh>
          </geometry>
          <material>
            <script>
              <name>Gazebo/DarkGrey</name>
              <uri>file://media/materials/scripts/gazebo.material</uri>
            </script>
          </material>
        </visual>
        <self_collide>0</self_collide>
        <enable_wind>0</enable_wind>
        <kinematic>0</kinematic>
      </link>
      <joint name='caster_front_right_2_joint' type='revolute'>
        <pose relative_to='caster_front_right_1_link'>-0.016 0 -0.04 -1.5708 0 0</pose>
        <parent>caster_front_right_1_link</parent>
        <child>caster_front_right_2_link</child>
        <axis>
          <xyz>0 0 1</xyz>
          <limit>
            <lower>-1e+16</lower>
            <upper>1e+16</upper>
          </limit>
          <dynamics>
            <spring_reference>0</spring_reference>
            <spring_stiffness>0</spring_stiffness>
          </dynamics>
        </axis>
      </joint>
      <link name='caster_front_right_2_link'>
        <pose relative_to='caster_front_right_2_joint'>0 0 0 0 -0 0</pose>
        <inertial>
          <pose>0 0 0 0 -0 0</pose>
          <mass>0.0885578</mass>
          <inertia>
            <ixx>1.075e-05</ixx>
            <ixy>0</ixy>
            <ixz>0</ixz>
            <iyy>1.541e-05</iyy>
            <iyz>0</iyz>
            <izz>1.075e-05</izz>
          </inertia>
        </inertial>
        <collision name='caster_front_right_2_link_collision'>
          <pose>0 0 0 0 -0 0</pose>
          <geometry>
            <sphere>
              <radius>0.025</radius>
            </sphere>
          </geometry>
          <surface>
            <contact>
              <ode>
                <kp>1e+07</kp>
                <kd>10</kd>
                <max_vel>10</max_vel>
                <min_depth>0.0005</min_depth>
              </ode>
            </contact>
            <friction>
              <ode>
                <mu>0.1</mu>
                <mu2>0.1</mu2>
              </ode>
              <torsional>
                <ode/>
              </torsional>
            </friction>
            <bounce/>
          </surface>
          <max_contacts>10</max_contacts>
        </collision>
        <visual name='caster_front_right_2_link_visual'>
          <pose>0 0 0 0 -0 0</pose>
          <geometry>
            <mesh>
              <scale>1 1 1</scale>
              <uri>/home/jin/ros/tiago_ws/src/pmb2_robot/pmb2_description/meshes/wheels/caster_2.stl</uri>
            </mesh>
          </geometry>
          <material>
            <script>
              <name>Gazebo/DarkGrey</name>
              <uri>file://media/materials/scripts/gazebo.material</uri>
            </script>
          </material>
        </visual>
        <self_collide>0</self_collide>
        <enable_wind>0</enable_wind>
        <kinematic>0</kinematic>
      </link>
      <joint name='suspension_left_joint' type='prismatic'>
        <pose relative_to='base_footprint'>0 0 0.0985 0 -0 0</pose>
        <parent>base_footprint</parent>
        <child>suspension_left_link</child>
        <axis>
          <xyz>0 0 1</xyz>
          <limit>
            <lower>-0.005</lower>
            <upper>0.005</upper>
            <effort>100</effort>
            <velocity>1</velocity>
          </limit>
          <dynamics>
            <damping>100</damping>
            <friction>0</friction>
            <spring_reference>0</spring_reference>
            <spring_stiffness>0</spring_stiffness>
          </dynamics>
        </axis>
      </joint>
      <link name='suspension_left_link'>
        <pose relative_to='suspension_left_joint'>0 0 0 0 -0 0</pose>
        <inertial>
          <pose>0 0 -0.02 0 -0 0</pose>
          <mass>10</mass>
          <inertia>
            <ixx>1</ixx>
            <ixy>0</ixy>
            <ixz>0</ixz>
            <iyy>1</iyy>
            <iyz>0</iyz>
            <izz>1</izz>
          </inertia>
        </inertial>
        <self_collide>0</self_collide>
        <enable_wind>0</enable_wind>
        <kinematic>0</kinematic>
      </link>
      <joint name='wheel_left_joint' type='revolute'>
        <pose relative_to='suspension_left_link'>0 0.2022 0 -1.5708 0 0</pose>
        <parent>suspension_left_link</parent>
        <child>wheel_left_link</child>
        <axis>
          <xyz>0 0 1</xyz>
          <limit>
            <effort>6</effort>
            <velocity>10.1523</velocity>
            <lower>-1e+16</lower>
            <upper>1e+16</upper>
          </limit>
          <dynamics>
            <spring_reference>0</spring_reference>
            <spring_stiffness>0</spring_stiffness>
          </dynamics>
        </axis>
      </joint>
      <link name='wheel_left_link'>
        <pose relative_to='wheel_left_joint'>0 0 0 0 -0 0</pose>
        <inertial>
          <pose>0 0 0.00207 0 -0 0</pose>
          <mass>1.82362</mass>
          <inertia>
            <ixx>0.00499743</ixx>
            <ixy>-4.464e-08</ixy>
            <ixz>-2.245e-08</ixz>
            <iyy>0.00499742</iyy>
            <iyz>1.64e-09</iyz>
            <izz>0.0083924</izz>
          </inertia>
        </inertial>
        <collision name='wheel_left_link_collision'>
          <pose>0 0 0 0 -0 0</pose>
          <geometry>
            <cylinder>
              <length>0.02</length>
              <radius>0.0985</radius>
            </cylinder>
          </geometry>
          <surface>
            <contact>
              <ode>
                <kp>1e+06</kp>
                <kd>100</kd>
                <max_vel>1</max_vel>
                <min_depth>0.002</min_depth>
              </ode>
            </contact>
            <friction>
              <ode>
                <mu>1e+14</mu>
                <mu2>1e+14</mu2>
              </ode>
              <torsional>
                <ode/>
              </torsional>
            </friction>
            <bounce/>
          </surface>
          <max_contacts>10</max_contacts>
        </collision>
        <visual name='wheel_left_link_visual'>
          <pose>0 0 0 -3.14159 0 0</pose>
          <geometry>
            <mesh>
              <scale>1 1 1</scale>
              <uri>/home/jin/ros/tiago_ws/src/pmb2_robot/pmb2_description/meshes/wheels/wheel.stl</uri>
            </mesh>
          </geometry>
          <material>
            <script>
              <name>Gazebo/DarkGrey</name>
              <uri>file://media/materials/scripts/gazebo.material</uri>
            </script>
          </material>
        </visual>
        <self_collide>0</self_collide>
        <enable_wind>0</enable_wind>
        <kinematic>0</kinematic>
      </link>
      <joint name='suspension_right_joint' type='prismatic'>
        <pose relative_to='base_footprint'>0 0 0.0985 0 -0 0</pose>
        <parent>base_footprint</parent>
        <child>suspension_right_link</child>
        <axis>
          <xyz>0 0 1</xyz>
          <limit>
            <lower>-0.005</lower>
            <upper>0.005</upper>
            <effort>100</effort>
            <velocity>1</velocity>
          </limit>
          <dynamics>
            <damping>100</damping>
            <friction>0</friction>
            <spring_reference>0</spring_reference>
            <spring_stiffness>0</spring_stiffness>
          </dynamics>
        </axis>
      </joint>
      <link name='suspension_right_link'>
        <pose relative_to='suspension_right_joint'>0 0 0 0 -0 0</pose>
        <inertial>
          <pose>0 0 -0.02 0 -0 0</pose>
          <mass>10</mass>
          <inertia>
            <ixx>1</ixx>
            <ixy>0</ixy>
            <ixz>0</ixz>
            <iyy>1</iyy>
            <iyz>0</iyz>
            <izz>1</izz>
          </inertia>
        </inertial>
        <self_collide>0</self_collide>
        <enable_wind>0</enable_wind>
        <kinematic>0</kinematic>
      </link>
      <joint name='wheel_right_joint' type='revolute'>
        <pose relative_to='suspension_right_link'>0 -0.2022 0 -1.5708 0 0</pose>
        <parent>suspension_right_link</parent>
        <child>wheel_right_link</child>
        <axis>
          <xyz>0 0 1</xyz>
          <limit>
            <effort>6</effort>
            <velocity>10.1523</velocity>
            <lower>-1e+16</lower>
            <upper>1e+16</upper>
          </limit>
          <dynamics>
            <spring_reference>0</spring_reference>
            <spring_stiffness>0</spring_stiffness>
          </dynamics>
        </axis>
      </joint>
      <link name='wheel_right_link'>
        <pose relative_to='wheel_right_joint'>0 0 0 0 -0 0</pose>
        <inertial>
          <pose>0 0 -0.00207 0 -0 0</pose>
          <mass>1.82362</mass>
          <inertia>
            <ixx>0.00499743</ixx>
            <ixy>4.464e-08</ixy>
            <ixz>-2.245e-08</ixz>
            <iyy>0.00499742</iyy>
            <iyz>-1.64e-09</iyz>
            <izz>0.0083924</izz>
          </inertia>
        </inertial>
        <collision name='wheel_right_link_collision'>
          <pose>0 0 0 0 -0 0</pose>
          <geometry>
            <cylinder>
              <length>0.02</length>
              <radius>0.0985</radius>
            </cylinder>
          </geometry>
          <surface>
            <contact>
              <ode>
                <kp>1e+06</kp>
                <kd>100</kd>
                <max_vel>1</max_vel>
                <min_depth>0.002</min_depth>
              </ode>
            </contact>
            <friction>
              <ode>
                <mu>1e+14</mu>
                <mu2>1e+14</mu2>
              </ode>
              <torsional>
                <ode/>
              </torsional>
            </friction>
            <bounce/>
          </surface>
          <max_contacts>10</max_contacts>
        </collision>
        <visual name='wheel_right_link_visual'>
          <pose>0 0 0 0 -0 0</pose>
          <geometry>
            <mesh>
              <scale>1 1 1</scale>
              <uri>/home/jin/ros/tiago_ws/src/pmb2_robot/pmb2_description/meshes/wheels/wheel.stl</uri>
            </mesh>
          </geometry>
          <material>
            <script>
              <name>Gazebo/DarkGrey</name>
              <uri>file://media/materials/scripts/gazebo.material</uri>
            </script>
          </material>
        </visual>
        <self_collide>0</self_collide>
        <enable_wind>0</enable_wind>
        <kinematic>0</kinematic>
      </link>
      <joint name='torso_lift_joint' type='prismatic'>
        <pose relative_to='base_footprint'>-0.062 0 0.8885 0 -0 0</pose>
        <parent>base_footprint</parent>
        <child>torso_lift_link</child>
        <axis>
          <xyz>0 0 1</xyz>
          <limit>
            <lower>0</lower>
            <upper>0.35</upper>
            <effort>2000</effort>
            <velocity>0.07</velocity>
          </limit>
          <dynamics>
            <damping>1000</damping>
            <friction>0</friction>
            <spring_reference>0</spring_reference>
            <spring_stiffness>0</spring_stiffness>
          </dynamics>
        </axis>
      </joint>
      <link name='torso_lift_link'>
        <pose relative_to='torso_lift_joint'>0 0 0 0 -0 0</pose>
        <inertial>
          <pose>0.04361 -0.00116 -0.17334 0 -0 0</pose>
          <mass>6.93198</mass>
          <inertia>
            <ixx>0.24487</ixx>
            <ixy>-0.001456</ixy>
            <ixz>-0.009742</ixz>
            <iyy>0.249269</iyy>
            <iyz>0.008281</iyz>
            <izz>0.090395</izz>
          </inertia>
        </inertial>
        <collision name='torso_lift_link_collision'>
          <pose>0 0 0 0 -0 0</pose>
          <geometry>
            <mesh>
              <scale>1 1 1</scale>
              <uri>/home/jin/ros/tiago_ws/src/tiago_robot/tiago_description/meshes/torso/torso_lift_collision_core.dae</uri>
            </mesh>
          </geometry>
          <max_contacts>10</max_contacts>
          <surface>
            <contact>
              <ode/>
            </contact>
            <bounce/>
            <friction>
              <torsional>
                <ode/>
              </torsional>
              <ode/>
            </friction>
          </surface>
        </collision>
        <collision name='torso_lift_link_collision_1'>
          <pose>0 0 0 0 -0 0</pose>
          <geometry>
            <mesh>
              <scale>1 1 1</scale>
              <uri>/home/jin/ros/tiago_ws/src/tiago_robot/tiago_description/meshes/torso/torso_lift_collision_shoulder.dae</uri>
            </mesh>
          </geometry>
          <max_contacts>10</max_contacts>
          <surface>
            <contact>
              <ode/>
            </contact>
            <bounce/>
            <friction>
              <torsional>
                <ode/>
              </torsional>
              <ode/>
            </friction>
          </surface>
        </collision>
        <collision name='torso_lift_link_collision_2'>
          <pose>0 0 0 0 -0 0</pose>
          <geometry>
            <mesh>
              <scale>1 1 1</scale>
              <uri>/home/jin/ros/tiago_ws/src/tiago_robot/tiago_description/meshes/torso/torso_lift_collision_neck.dae</uri>
            </mesh>
          </geometry>
          <max_contacts>10</max_contacts>
          <surface>
            <contact>
              <ode/>
            </contact>
            <bounce/>
            <friction>
              <torsional>
                <ode/>
              </torsional>
              <ode/>
            </friction>
          </surface>
        </collision>
        <visual name='torso_lift_link_visual'>
          <pose>0 0 0 0 -0 0</pose>
          <geometry>
            <mesh>
              <scale>1 1 1</scale>
              <uri>/home/jin/ros/tiago_ws/src/tiago_robot/tiago_description/meshes/torso/torso_lift_with_arm.stl</uri>
            </mesh>
          </geometry>
        </visual>
        <self_collide>0</self_collide>
        <enable_wind>0</enable_wind>
        <kinematic>0</kinematic>
      </link>
      <joint name='arm_1_joint' type='revolute'>
        <pose relative_to='torso_lift_link'>0.15505 0.014 -0.151 0 0 -1.5708</pose>
        <parent>torso_lift_link</parent>
        <child>arm_1_link</child>
        <axis>
          <xyz>0 0 1</xyz>
          <limit>
            <lower>0</lower>
            <upper>2.74889</upper>
            <effort>43</effort>
            <velocity>1.95</velocity>
          </limit>
          <dynamics>
            <damping>1</damping>
            <friction>1</friction>
            <spring_reference>0</spring_reference>
            <spring_stiffness>0</spring_stiffness>
          </dynamics>
        </axis>
        <physics>
          <ode>
            <implicit_spring_damper>1</implicit_spring_damper>
            <cfm_damping>1</cfm_damping>
            <limit>
              <cfm>0</cfm>
              <erp>0.2</erp>
            </limit>
          </ode>
        </physics>
      </joint>
      <link name='arm_1_link'>
        <pose relative_to='arm_1_joint'>0 0 0 0 -0 0</pose>
        <inertial>
          <pose>0.061191 -0.022397 -0.012835 0 -0 0</pose>
          <mass>1.56343</mass>
          <inertia>
            <ixx>0.002471</ixx>
            <ixy>-0.001809</ixy>
            <ixz>-0.001202</ixz>
            <iyy>0.006132</iyy>
            <iyz>0.000494</iyz>
            <izz>0.006704</izz>
          </inertia>
        </inertial>
        <collision name='arm_1_link_collision'>
          <pose>0 0 0 0 -0 0</pose>
          <geometry>
            <mesh>
              <scale>1 1 1</scale>
              <uri>/home/jin/ros/tiago_ws/src/tiago_robot/tiago_description/meshes/arm/arm_1_collision.dae</uri>
            </mesh>
          </geometry>
          <surface>
            <contact>
              <ode/>
            </contact>
            <friction>
              <ode>
                <mu>0.9</mu>
                <mu2>0.9</mu2>
              </ode>
              <torsional>
                <ode/>
              </torsional>
            </friction>
            <bounce/>
          </surface>
          <max_contacts>10</max_contacts>
        </collision>
        <visual name='arm_1_link_visual'>
          <pose>0 0 0 0 -0 0</pose>
          <geometry>
            <mesh>
              <scale>1 1 1</scale>
              <uri>/home/jin/ros/tiago_ws/src/tiago_robot/tiago_description/meshes/arm/arm_1.stl</uri>
            </mesh>
          </geometry>
          <material>
            <script>
              <name>Gazebo/DarkGrey</name>
              <uri>file://media/materials/scripts/gazebo.material</uri>
            </script>
          </material>
        </visual>
        <self_collide>0</self_collide>
        <enable_wind>0</enable_wind>
        <kinematic>0</kinematic>
      </link>
      <joint name='arm_2_joint' type='revolute'>
        <pose relative_to='arm_1_link'>0.125 0.0195 -0.031 1.5708 -0 0</pose>
        <parent>arm_1_link</parent>
        <child>arm_2_link</child>
        <axis>
          <xyz>0 0 1</xyz>
          <limit>
            <lower>-1.5708</lower>
            <upper>1.09083</upper>
            <effort>43</effort>
            <velocity>1.95</velocity>
          </limit>
          <dynamics>
            <damping>1</damping>
            <friction>1</friction>
            <spring_reference>0</spring_reference>
            <spring_stiffness>0</spring_stiffness>
          </dynamics>
        </axis>
        <physics>
          <ode>
            <implicit_spring_damper>1</implicit_spring_damper>
            <cfm_damping>1</cfm_damping>
            <limit>
              <cfm>0</cfm>
              <erp>0.2</erp>
            </limit>
          </ode>
        </physics>
      </joint>
      <link name='arm_2_link'>
        <pose relative_to='arm_2_joint'>0 0 0 0 -0 0</pose>
        <inertial>
          <pose>0.030432 0.000229 -0.005942 0 -0 0</pose>
          <mass>1.8004</mass>
          <inertia>
            <ixx>0.001809</ixx>
            <ixy>1.5e-05</ixy>
            <ixz>0.000254</ixz>
            <iyy>0.004333</iyy>
            <iyz>1.4e-05</iyz>
            <izz>0.004341</izz>
          </inertia>
        </inertial>
        <collision name='arm_2_link_collision'>
          <pose>0 0 0 0 -0 0</pose>
          <geometry>
            <mesh>
              <scale>1 1 1</scale>
              <uri>/home/jin/ros/tiago_ws/src/tiago_robot/tiago_description/meshes/arm/arm_2_collision.dae</uri>
            </mesh>
          </geometry>
          <surface>
            <contact>
              <ode/>
            </contact>
            <friction>
              <ode>
                <mu>0.9</mu>
                <mu2>0.9</mu2>
              </ode>
              <torsional>
                <ode/>
              </torsional>
            </friction>
            <bounce/>
          </surface>
          <max_contacts>10</max_contacts>
        </collision>
        <visual name='arm_2_link_visual'>
          <pose>0 0 0 0 -0 0</pose>
          <geometry>
            <mesh>
              <scale>1 1 1</scale>
              <uri>/home/jin/ros/tiago_ws/src/tiago_robot/tiago_description/meshes/arm/arm_2.stl</uri>
            </mesh>
          </geometry>
          <material>
            <script>
              <name>Gazebo/DarkGrey</name>
              <uri>file://media/materials/scripts/gazebo.material</uri>
            </script>
          </material>
        </visual>
        <self_collide>0</self_collide>
        <enable_wind>0</enable_wind>
        <kinematic>0</kinematic>
      </link>
      <joint name='arm_3_joint' type='revolute'>
        <pose relative_to='arm_2_link'>0.0895 0 -0.0015 -1.5708 0 1.5708</pose>
        <parent>arm_2_link</parent>
        <child>arm_3_link</child>
        <axis>
          <xyz>0 0 1</xyz>
          <limit>
            <lower>-3.53429</lower>
            <upper>1.5708</upper>
            <effort>26</effort>
            <velocity>2.35</velocity>
          </limit>
          <dynamics>
            <damping>1</damping>
            <friction>1</friction>
            <spring_reference>0</spring_reference>
            <spring_stiffness>0</spring_stiffness>
          </dynamics>
        </axis>
        <physics>
          <ode>
            <implicit_spring_damper>1</implicit_spring_damper>
            <cfm_damping>1</cfm_damping>
            <limit>
              <cfm>0</cfm>
              <erp>0.2</erp>
            </limit>
          </ode>
        </physics>
      </joint>
      <link name='arm_3_link'>
        <pose relative_to='arm_3_joint'>0 0 0 0 -0 0</pose>
        <inertial>
          <pose>0.007418 -0.004361 -0.134194 0 -0 0</pose>
          <mass>1.8</mass>
          <inertia>
            <ixx>0.019541</ixx>
            <ixy>-0.000105</ixy>
            <ixz>-0.001717</ixz>
            <iyy>0.019936</iyy>
            <iyz>0.000852</iyz>
            <izz>0.002864</izz>
          </inertia>
        </inertial>
        <collision name='arm_3_link_collision'>
          <pose>0 0 0 0 -0 0</pose>
          <geometry>
            <mesh>
              <scale>1 1 1</scale>
              <uri>/home/jin/ros/tiago_ws/src/tiago_robot/tiago_description/meshes/arm/arm_3_collision.dae</uri>
            </mesh>
          </geometry>
          <surface>
            <contact>
              <ode/>
            </contact>
            <friction>
              <ode>
                <mu>0.9</mu>
                <mu2>0.9</mu2>
              </ode>
              <torsional>
                <ode/>
              </torsional>
            </friction>
            <bounce/>
          </surface>
          <max_contacts>10</max_contacts>
        </collision>
        <visual name='arm_3_link_visual'>
          <pose>0 0 0 0 -0 0</pose>
          <geometry>
            <mesh>
              <scale>1 1 1</scale>
              <uri>/home/jin/ros/tiago_ws/src/tiago_robot/tiago_description/meshes/arm/arm_3.stl</uri>
            </mesh>
          </geometry>
          <material>
            <script>
              <name>Gazebo/DarkGrey</name>
              <uri>file://media/materials/scripts/gazebo.material</uri>
            </script>
          </material>
        </visual>
        <self_collide>0</self_collide>
        <enable_wind>0</enable_wind>
        <kinematic>0</kinematic>
      </link>
      <joint name='arm_4_joint' type='revolute'>
        <pose relative_to='arm_3_link'>-0.02 -0.027 -0.222 1.57079 -1.57079 3.14159</pose>
        <parent>arm_3_link</parent>
        <child>arm_4_link</child>
        <axis>
          <xyz>0 0 1</xyz>
          <limit>
            <lower>-0.392699</lower>
            <upper>2.35619</upper>
            <effort>26</effort>
            <velocity>2.35</velocity>
          </limit>
          <dynamics>
            <damping>1</damping>
            <friction>1</friction>
            <spring_reference>0</spring_reference>
            <spring_stiffness>0</spring_stiffness>
          </dynamics>
        </axis>
        <physics>
          <ode>
            <implicit_spring_damper>1</implicit_spring_damper>
            <cfm_damping>1</cfm_damping>
            <limit>
              <cfm>0</cfm>
              <erp>0.2</erp>
            </limit>
          </ode>
        </physics>
      </joint>
      <link name='arm_4_link'>
        <pose relative_to='arm_4_joint'>0 0 0 0 -0 0</pose>
        <inertial>
          <pose>-0.095658 0.014666 0.018133 0 -0 0</pose>
          <mass>1.4327</mass>
          <inertia>
            <ixx>0.00204</ixx>
            <ixy>0.000725</ixy>
            <ixz>-0.00115</ixz>
            <iyy>0.008424</iyy>
            <iyz>-0.000204</iyz>
            <izz>0.008686</izz>
          </inertia>
        </inertial>
        <collision name='arm_4_link_collision'>
          <pose>0 0 0 0 -0 0</pose>
          <geometry>
            <mesh>
              <scale>1 1 1</scale>
              <uri>/home/jin/ros/tiago_ws/src/tiago_robot/tiago_description/meshes/arm/arm_4_collision.dae</uri>
            </mesh>
          </geometry>
          <surface>
            <contact>
              <ode/>
            </contact>
            <friction>
              <ode>
                <mu>0.9</mu>
                <mu2>0.9</mu2>
              </ode>
              <torsional>
                <ode/>
              </torsional>
            </friction>
            <bounce/>
          </surface>
          <max_contacts>10</max_contacts>
        </collision>
        <visual name='arm_4_link_visual'>
          <pose>0 0 0 0 -0 0</pose>
          <geometry>
            <mesh>
              <scale>1 1 1</scale>
              <uri>/home/jin/ros/tiago_ws/src/tiago_robot/tiago_description/meshes/arm/arm_4.stl</uri>
            </mesh>
          </geometry>
          <material>
            <script>
              <name>Gazebo/DarkGrey</name>
              <uri>file://media/materials/scripts/gazebo.material</uri>
            </script>
          </material>
        </visual>
        <self_collide>0</self_collide>
        <enable_wind>0</enable_wind>
        <kinematic>0</kinematic>
      </link>
      <joint name='arm_5_joint' type='revolute'>
        <pose relative_to='arm_4_link'>-0.162 0.02 0.027 3.14159 -1.57079 3.14159</pose>
        <parent>arm_4_link</parent>
        <child>arm_5_link</child>
        <axis>
          <xyz>0 0 1</xyz>
          <limit>
            <lower>-2.0944</lower>
            <upper>2.0944</upper>
            <effort>3</effort>
            <velocity>1.95</velocity>
          </limit>
          <dynamics>
            <damping>1</damping>
            <friction>1</friction>
            <spring_reference>0</spring_reference>
            <spring_stiffness>0</spring_stiffness>
          </dynamics>
        </axis>
        <physics>
          <ode>
            <implicit_spring_damper>1</implicit_spring_damper>
            <cfm_damping>1</cfm_damping>
            <limit>
              <cfm>0</cfm>
              <erp>0.2</erp>
            </limit>
          </ode>
        </physics>
      </joint>
      <link name='arm_5_link'>
        <pose relative_to='arm_5_joint'>0 0 0 0 -0 0</pose>
        <inertial>
          <pose>0.001078 -0.000151 -0.077173 0 -0 0</pose>
          <mass>0.935914</mass>
          <inertia>
            <ixx>0.00103619</ixx>
            <ixy>1.06223e-07</ixy>
            <ixz>1.99203e-06</ixz>
            <iyy>0.000794527</iyy>
            <iyz>-2.56396e-07</iyz>
            <izz>0.000439831</izz>
          </inertia>
        </inertial>
        <collision name='arm_5_link_collision'>
          <pose>0 0 0 0 -0 0</pose>
          <geometry>
            <mesh>
              <scale>1 1 1</scale>
              <uri>/home/jin/ros/tiago_ws/src/tiago_robot/tiago_description/meshes/arm/arm_5_collision-wrist-2017.dae</uri>
            </mesh>
          </geometry>
          <surface>
            <contact>
              <ode/>
            </contact>
            <friction>
              <ode>
                <mu>0.9</mu>
                <mu2>0.9</mu2>
              </ode>
              <torsional>
                <ode/>
              </torsional>
            </friction>
            <bounce/>
          </surface>
          <max_contacts>10</max_contacts>
        </collision>
        <visual name='arm_5_link_visual'>
          <pose>0 0 0 0 -0 0</pose>
          <geometry>
            <mesh>
              <scale>1 1 1</scale>
              <uri>/home/jin/ros/tiago_ws/src/tiago_robot/tiago_description/meshes/arm/arm_5-wrist-2017.stl</uri>
            </mesh>
          </geometry>
        </visual>
        <self_collide>0</self_collide>
        <enable_wind>0</enable_wind>
        <kinematic>0</kinematic>
      </link>
      <joint name='arm_6_joint' type='revolute'>
        <pose relative_to='arm_5_link'>0 0 0.15 1.57079 -1.57079 3.14159</pose>
        <parent>arm_5_link</parent>
        <child>arm_6_link</child>
        <axis>
          <xyz>0 0 1</xyz>
          <limit>
            <lower>-1.41372</lower>
            <upper>1.41372</upper>
            <effort>6.6</effort>
            <velocity>1.76</velocity>
          </limit>
          <dynamics>
            <damping>1</damping>
            <friction>1</friction>
            <spring_reference>0</spring_reference>
            <spring_stiffness>0</spring_stiffness>
          </dynamics>
        </axis>
        <physics>
          <ode>
            <implicit_spring_damper>1</implicit_spring_damper>
            <cfm_damping>1</cfm_damping>
            <limit>
              <cfm>0</cfm>
              <erp>0.2</erp>
            </limit>
          </ode>
        </physics>
      </joint>
      <link name='arm_6_link'>
        <pose relative_to='arm_6_joint'>0 0 0 0 -0 0</pose>
        <inertial>
          <pose>-0.000153 -0.003122 0.000183 0 -0 0</pose>
          <mass>0.302758</mass>
          <inertia>
            <ixx>3.29234e-05</ixx>
            <ixy>6.31537e-08</ixy>
            <ixz>-4.56712e-11</ixz>
            <iyy>3.85334e-05</iyy>
            <iyz>-2.01613e-07</iyz>
            <izz>3.33283e-05</izz>
          </inertia>
        </inertial>
        <collision name='arm_6_link_collision'>
          <pose>0 0 0 0 -0 0</pose>
          <geometry>
            <mesh>
              <scale>1 1 1</scale>
              <uri>/home/jin/ros/tiago_ws/src/tiago_robot/tiago_description/meshes/arm/arm_6_collision-wrist-2017.dae</uri>
            </mesh>
          </geometry>
          <surface>
            <contact>
              <ode/>
            </contact>
            <friction>
              <ode>
                <mu>0.9</mu>
                <mu2>0.9</mu2>
              </ode>
              <torsional>
                <ode/>
              </torsional>
            </friction>
            <bounce/>
          </surface>
          <max_contacts>10</max_contacts>
        </collision>
        <visual name='arm_6_link_visual'>
          <pose>0 0 0 0 -0 0</pose>
          <geometry>
            <mesh>
              <scale>1 1 1</scale>
              <uri>/home/jin/ros/tiago_ws/src/tiago_robot/tiago_description/meshes/arm/arm_6-wrist-2017.stl</uri>
            </mesh>
          </geometry>
        </visual>
        <self_collide>0</self_collide>
        <enable_wind>0</enable_wind>
        <kinematic>0</kinematic>
      </link>
      <joint name='arm_7_joint' type='revolute'>
        <pose relative_to='arm_6_link'>0 0 0 1.5708 -0 1.5708</pose>
        <parent>arm_6_link</parent>
        <child>arm_7_link</child>
        <axis>
          <xyz>0 0 1</xyz>
          <limit>
            <lower>-2.0944</lower>
            <upper>2.0944</upper>
            <effort>6.6</effort>
            <velocity>1.76</velocity>
          </limit>
          <dynamics>
            <damping>1</damping>
            <friction>1</friction>
            <spring_reference>0</spring_reference>
            <spring_stiffness>0</spring_stiffness>
          </dynamics>
        </axis>
        <physics>
          <provide_feedback>1</provide_feedback>
          <ode>
            <implicit_spring_damper>1</implicit_spring_damper>
            <cfm_damping>1</cfm_damping>
            <limit>
              <cfm>0</cfm>
              <erp>0.2</erp>
            </limit>
            <provide_feedback>1</provide_feedback>
          </ode>
        </physics>
      </joint>
      <link name='arm_7_link'>
        <pose relative_to='arm_7_joint'>0 0 0 0 -0 0</pose>
        <inertial>
          <pose>-0.000217 0.00022 0.081541 0 -0 0</pose>
          <mass>0.80276</mass>
          <inertia>
            <ixx>0.00211687</ixx>
            <ixy>4.48741e-05</ixy>
            <ixz>3.40015e-06</ixz>
            <iyy>0.00178615</iyy>
            <iyz>-3.38361e-06</iyz>
            <izz>0.000703049</izz>
          </inertia>
        </inertial>
        <collision name='arm_7_link_fixed_joint_lump__arm_tool_link_collision'>
          <pose>-0 0 0.0583 0 -0 -1.5708</pose>
          <geometry>
            <cylinder>
              <length>0.005</length>
              <radius>0.005</radius>
            </cylinder>
          </geometry>
          <max_contacts>10</max_contacts>
          <surface>
            <contact>
              <ode/>
            </contact>
            <bounce/>
            <friction>
              <torsional>
                <ode/>
              </torsional>
              <ode/>
            </friction>
          </surface>
        </collision>
        <collision name='arm_7_link_fixed_joint_lump__gripper_link_collision_1'>
          <pose>-0 -0 0.0673 3.14159 -0 -1.5708</pose>
          <geometry>
            <mesh>
              <scale>1 1 1</scale>
              <uri>/home/jin/ros/tiago_ws/src/pal_gripper/pal_gripper_description/meshes/gripper_link_collision.stl</uri>
            </mesh>
          </geometry>
          <surface>
            <contact>
              <ode/>
            </contact>
            <friction>
              <ode/>
              <torsional>
                <ode/>
              </torsional>
            </friction>
            <bounce/>
          </surface>
          <max_contacts>10</max_contacts>
        </collision>
        <visual name='arm_7_link_fixed_joint_lump__arm_tool_link_visual'>
          <pose>-0 0 0.0583 0 -0 -1.5708</pose>
          <geometry>
            <cylinder>
              <length>0.005</length>
              <radius>0.005</radius>
            </cylinder>
          </geometry>
        </visual>
        <visual name='arm_7_link_fixed_joint_lump__gripper_link_visual_1'>
          <pose>-0 -0 0.0673 3.14159 -0 -1.5708</pose>
          <geometry>
            <mesh>
              <scale>1 1 1</scale>
              <uri>/home/jin/ros/tiago_ws/src/pal_gripper/pal_gripper_description/meshes/gripper_link.stl</uri>
            </mesh>
          </geometry>
          <material>
            <script>
              <name>Gazebo/White</name>
              <uri>file://media/materials/scripts/gazebo.material</uri>
            </script>
          </material>
        </visual>
        <self_collide>0</self_collide>
        <enable_wind>0</enable_wind>
        <kinematic>0</kinematic>
      </link>
      <joint name='gripper_left_finger_joint' type='prismatic'>
        <pose relative_to='arm_7_link'>-0 -0 0.0673 3.14159 -0 -1.5708</pose>
        <parent>arm_7_link</parent>
        <child>gripper_left_finger_link</child>
        <axis>
          <xyz>-1 0 0</xyz>
          <limit>
            <lower>0</lower>
            <upper>0.045</upper>
            <effort>64</effort>
            <velocity>0.05</velocity>
          </limit>
          <dynamics>
            <damping>1</damping>
            <friction>0</friction>
            <spring_reference>0</spring_reference>
            <spring_stiffness>0</spring_stiffness>
          </dynamics>
        </axis>
        <physics>
          <provide_feedback>1</provide_feedback>
          <ode>
            <implicit_spring_damper>1</implicit_spring_damper>
            <cfm_damping>1</cfm_damping>
            <limit>
              <cfm>0</cfm>
              <erp>0.2</erp>
            </limit>
            <provide_feedback>1</provide_feedback>
          </ode>
        </physics>
      </joint>
      <link name='gripper_left_finger_link'>
        <pose relative_to='gripper_left_finger_joint'>0 0 0 0 -0 0</pose>
        <inertial>
          <pose>-0.00447 0.010766 -0.121013 0 -0 0</pose>
          <mass>0.10998</mass>
          <inertia>
            <ixx>0.000232</ixx>
            <ixy>-5e-06</ixy>
            <ixz>-3.2e-05</ixz>
            <iyy>0.000224</iyy>
            <iyz>3.6e-05</iyz>
            <izz>2.9e-05</izz>
          </inertia>
        </inertial>
        <collision name='gripper_left_finger_link_collision'>
          <pose>-0.005 0 -0.165 0 -0 3.1415</pose>
          <geometry>
            <box>
              <size>0.01 0.05 0.11</size>
            </box>
          </geometry>
          <surface>
            <friction>
              <torsional>
                <coefficient>1000</coefficient>
                <use_patch_radius>1</use_patch_radius>
                <patch_radius>0.1</patch_radius>
                <ode/>
              </torsional>
              <ode>
                <mu>inf</mu>
                <mu2>inf</mu2>
                <fdir1>1 0 0</fdir1>
              </ode>
            </friction>
            <contact>
              <poissons_ratio>1</poissons_ratio>
              <elastic_modulus>inf</elastic_modulus>
              <ode>
                <kp>inf</kp>
                <kd>100</kd>
                <max_vel>0</max_vel>
                <min_depth>0.002</min_depth>
              </ode>
            </contact>
            <bounce/>
          </surface>
          <max_contacts>100</max_contacts>
        </collision>
        <visual name='gripper_left_finger_link_visual'>
          <pose>0 0 0 0 -0 3.1415</pose>
          <geometry>
            <mesh>
              <scale>1 1 1</scale>
              <uri>/home/jin/ros/tiago_ws/src/pal_gripper/pal_gripper_description/meshes/gripper_finger_link.stl</uri>
            </mesh>
          </geometry>
          <material>
            <script>
              <name>Gazebo/Black</name>
              <uri>file://media/materials/scripts/gazebo.material</uri>
            </script>
          </material>
        </visual>
        <self_collide>0</self_collide>
        <enable_wind>0</enable_wind>
        <kinematic>0</kinematic>
      </link>
      <joint name='gripper_right_finger_joint' type='prismatic'>
        <pose relative_to='arm_7_link'>-0 -0 0.0673 3.14159 -0 -1.5708</pose>
        <parent>arm_7_link</parent>
        <child>gripper_right_finger_link</child>
        <axis>
          <xyz>1 0 0</xyz>
          <limit>
            <lower>0</lower>
            <upper>0.045</upper>
            <effort>64</effort>
            <velocity>0.05</velocity>
          </limit>
          <dynamics>
            <damping>1</damping>
            <friction>0</friction>
            <spring_reference>0</spring_reference>
            <spring_stiffness>0</spring_stiffness>
          </dynamics>
        </axis>
        <physics>
          <provide_feedback>1</provide_feedback>
          <ode>
            <implicit_spring_damper>1</implicit_spring_damper>
            <cfm_damping>1</cfm_damping>
            <limit>
              <cfm>0</cfm>
              <erp>0.2</erp>
            </limit>
            <provide_feedback>1</provide_feedback>
          </ode>
        </physics>
      </joint>
      <link name='gripper_right_finger_link'>
        <pose relative_to='gripper_right_finger_joint'>0 0 0 0 -0 0</pose>
        <inertial>
          <pose>-0.00447 0.010766 -0.121013 0 -0 0</pose>
          <mass>0.10998</mass>
          <inertia>
            <ixx>0.000232</ixx>
            <ixy>-5e-06</ixy>
            <ixz>-3.2e-05</ixz>
            <iyy>0.000224</iyy>
            <iyz>3.6e-05</iyz>
            <izz>2.9e-05</izz>
          </inertia>
        </inertial>
        <collision name='gripper_right_finger_link_collision'>
          <pose>0.005 0 -0.165 0 -0 3.1415</pose>
          <geometry>
            <box>
              <size>0.01 0.05 0.11</size>
            </box>
          </geometry>
          <surface>
            <friction>
              <torsional>
                <coefficient>1000</coefficient>
                <use_patch_radius>1</use_patch_radius>
                <patch_radius>0.1</patch_radius>
                <ode/>
              </torsional>
              <ode>
                <mu>inf</mu>
                <mu2>inf</mu2>
                <fdir1>1 0 0</fdir1>
              </ode>
            </friction>
            <contact>
              <poissons_ratio>1</poissons_ratio>
              <elastic_modulus>inf</elastic_modulus>
              <ode>
                <kp>inf</kp>
                <kd>100</kd>
                <max_vel>0</max_vel>
                <min_depth>0.002</min_depth>
              </ode>
            </contact>
            <bounce/>
          </surface>
          <max_contacts>100</max_contacts>
        </collision>
        <visual name='gripper_right_finger_link_visual'>
          <pose>0 0 0 0 -0 3.1415</pose>
          <geometry>
            <mesh>
              <scale>-1 -1 1</scale>
              <uri>/home/jin/ros/tiago_ws/src/pal_gripper/pal_gripper_description/meshes/gripper_finger_link.stl</uri>
            </mesh>
          </geometry>
          <material>
            <script>
              <name>Gazebo/Black</name>
              <uri>file://media/materials/scripts/gazebo.material</uri>
            </script>
          </material>
        </visual>
        <self_collide>0</self_collide>
        <enable_wind>0</enable_wind>
        <kinematic>0</kinematic>
      </link>
      <joint name='head_1_joint' type='revolute'>
        <pose relative_to='torso_lift_link'>0.182 0 0 0 -0 0</pose>
        <parent>torso_lift_link</parent>
        <child>head_1_link</child>
        <axis>
          <xyz>0 0 1</xyz>
          <limit>
            <lower>-1.309</lower>
            <upper>1.309</upper>
            <effort>5.197</effort>
            <velocity>3</velocity>
          </limit>
          <dynamics>
            <damping>0.5</damping>
            <friction>1</friction>
            <spring_reference>0</spring_reference>
            <spring_stiffness>0</spring_stiffness>
          </dynamics>
        </axis>
        <physics>
          <ode>
            <implicit_spring_damper>1</implicit_spring_damper>
            <cfm_damping>1</cfm_damping>
            <limit>
              <cfm>0</cfm>
              <erp>0.2</erp>
            </limit>
          </ode>
        </physics>
      </joint>
      <link name='head_1_link'>
        <pose relative_to='head_1_joint'>0 0 0 0 -0 0</pose>
        <inertial>
          <pose>-0.00508 0.00237 0.07229 0 -0 0</pose>
          <mass>0.6222</mass>
          <inertia>
            <ixx>0.001192</ixx>
            <ixy>-7e-06</ixy>
            <ixz>9.6e-05</ixz>
            <iyy>0.001402</iyy>
            <iyz>4e-06</iyz>
            <izz>0.000889</izz>
          </inertia>
        </inertial>
        <collision name='head_1_link_collision'>
          <pose>0 0 0 0 -0 0</pose>
          <geometry>
            <mesh>
              <scale>1 1 1</scale>
              <uri>/home/jin/ros/tiago_ws/src/tiago_robot/tiago_description/meshes/head/head_1_collision.dae</uri>
            </mesh>
          </geometry>
          <surface>
            <contact>
              <ode/>
            </contact>
            <friction>
              <ode>
                <mu>0.9</mu>
                <mu2>0.9</mu2>
              </ode>
              <torsional>
                <ode/>
              </torsional>
            </friction>
            <bounce/>
          </surface>
          <max_contacts>10</max_contacts>
        </collision>
        <visual name='head_1_link_visual'>
          <pose>0 0 0 0 -0 0</pose>
          <geometry>
            <mesh>
              <scale>1 1 1</scale>
              <uri>/home/jin/ros/tiago_ws/src/tiago_robot/tiago_description/meshes/head/head_1.stl</uri>
            </mesh>
          </geometry>
        </visual>
        <self_collide>0</self_collide>
        <enable_wind>0</enable_wind>
        <kinematic>0</kinematic>
      </link>
      <joint name='head_2_joint' type='revolute'>
        <pose relative_to='head_1_link'>0.005 0 0.098 1.5708 -0 0</pose>
        <parent>head_1_link</parent>
        <child>head_2_link</child>
        <axis>
          <xyz>0 0 1</xyz>
          <limit>
            <lower>-1.0472</lower>
            <upper>0.785398</upper>
            <effort>2.77</effort>
            <velocity>3</velocity>
          </limit>
          <dynamics>
            <damping>0.5</damping>
            <friction>1</friction>
            <spring_reference>0</spring_reference>
            <spring_stiffness>0</spring_stiffness>
          </dynamics>
        </axis>
      </joint>
      <link name='head_2_link'>
        <pose relative_to='head_2_joint'>0 0 0 0 -0 0</pose>
        <inertial>
          <pose>0.055827 0.060999 1.6e-05 0 -0 0</pose>
          <mass>0.88693</mass>
          <inertia>
            <ixx>0.00477062</ixx>
            <ixy>0.000560916</ixy>
            <ixz>1.19415e-05</ixz>
            <iyy>0.00513368</iyy>
            <iyz>9.32647e-06</iyz>
            <izz>0.00347598</izz>
          </inertia>
        </inertial>
        <collision name='head_2_link_collision'>
          <pose>0 0 0 0 -0 0</pose>
          <geometry>
            <mesh>
              <scale>1 1 1</scale>
              <uri>/home/jin/ros/tiago_ws/src/tiago_robot/tiago_description/meshes/head/head_2_collision.dae</uri>
            </mesh>
          </geometry>
          <max_contacts>10</max_contacts>
          <surface>
            <contact>
              <ode/>
            </contact>
            <bounce/>
            <friction>
              <torsional>
                <ode/>
              </torsional>
              <ode/>
            </friction>
          </surface>
        </collision>
        <visual name='head_2_link_visual'>
          <pose>0 0 0 0 -0 0</pose>
          <geometry>
            <mesh>
              <scale>1 1 1</scale>
              <uri>/home/jin/ros/tiago_ws/src/tiago_robot/tiago_description/meshes/head/head_2.stl</uri>
            </mesh>
          </geometry>
        </visual>
        <sensor name='xtion_frame_sensor' type='depth'>
          <always_on>1</always_on>
          <update_rate>30</update_rate>
          <camera>
            <horizontal_fov>1.09956</horizontal_fov>
            <image>
              <format>B8G8R8</format>
              <width>640</width>
              <height>480</height>
            </image>
            <clip>
              <near>0.3</near>
              <far>8</far>
            </clip>
          </camera>
          <plugin name='xtion_frame_controller' filename='libgazebo_ros_openni_kinect.so'>
            <alwaysOn>1</alwaysOn>
            <updateRate>30.0</updateRate>
            <cameraName>xtion</cameraName>
            <imageTopicName>rgb/image_raw</imageTopicName>
            <cameraInfoTopicName>rgb/camera_info</cameraInfoTopicName>
            <depthImageTopicName>depth_registered/image_raw</depthImageTopicName>
            <depthImageCameraInfoTopicName>depth_registered/camera_info</depthImageCameraInfoTopicName>
            <pointCloudTopicName>depth_registered/points</pointCloudTopicName>
            <frameName>xtion_rgb_optical_frame</frameName>
            <pointCloudCutoff>0.5</pointCloudCutoff>
            <pointCloudCutoffMax>8.0</pointCloudCutoffMax>
            <distortionK1>0.00000001</distortionK1>
            <distortionK2>0.00000001</distortionK2>
            <distortionK3>0.00000001</distortionK3>
            <distortionT1>0.00000001</distortionT1>
            <distortionT2>0.00000001</distortionT2>
            <robotNamespace>/</robotNamespace>
          </plugin>
          <pose>0.0908 0.08 -0.022 -1.5708 0 0</pose>
        </sensor>
        <self_collide>0</self_collide>
        <enable_wind>0</enable_wind>
        <kinematic>0</kinematic>
      </link>
      <plugin name='gazebo_ros_control' filename='libgazebo_ros_control.so'>
        <ns/>
        <robotSimType>pal_hardware_gazebo/PalHardwareGazebo</robotSimType>
        <robotNamespace/>
        <controlPeriod>0.01</controlPeriod>
      </plugin>
      <plugin name='gazebo_ros_p3d' filename='libgazebo_ros_p3d.so'>
        <bodyName>base_footprint</bodyName>
        <topicName>ground_truth_odom</topicName>
        <alwaysOn>1</alwaysOn>
        <updateRate>100.0</updateRate>
        <robotNamespace>/</robotNamespace>
      </plugin>
      <plugin name='gazebo_ros_odometry' filename='libgazebo_world_odometry.so'>
        <frameName>base_footprint</frameName>
        <topicName>floating_base_pose_simulated</topicName>
        <robotNamespace>/</robotNamespace>
      </plugin>
      <static>0</static>
      <gripper name='gripper_grasp'>
        <grasp_check>
          <attach_steps>1</attach_steps>
          <detach_steps>1</detach_steps>
          <min_contact_count>3</min_contact_count>
        </grasp_check>
        <gripper_link>gripper_left_finger_link</gripper_link>
        <gripper_link>gripper_right_finger_link</gripper_link>
        <palm_link>arm_7_link</palm_link>
      </gripper>
      <pose>0 0 0 0 -0 0</pose>
    </model>
    <model name='beer'>
      <link name='link'>
        <pose>0 0 0.115 0 -0 0</pose>
        <inertial>
          <mass>0.39</mass>
          <inertia>
            <ixx>0.00058</ixx>
            <ixy>0</ixy>
            <ixz>0</ixz>
            <iyy>0.00058</iyy>
            <iyz>0</iyz>
            <izz>0.00019</izz>
          </inertia>
          <pose>0 0 0 0 -0 0</pose>
        </inertial>
        <collision name='collision'>
          <geometry>
            <cylinder>
              <radius>0.055</radius>
              <length>0.23</length>
            </cylinder>
          </geometry>
          <max_contacts>10</max_contacts>
          <surface>
            <contact>
              <ode/>
            </contact>
            <bounce/>
            <friction>
              <torsional>
                <ode/>
              </torsional>
              <ode/>
            </friction>
          </surface>
        </collision>
        <visual name='visual'>
          <geometry>
            <cylinder>
              <radius>0.055</radius>
              <length>0.23</length>
            </cylinder>
          </geometry>
          <material>
            <script>
              <uri>model://beer/materials/scripts</uri>
              <uri>model://beer/materials/textures</uri>
              <name>Beer/Diffuse</name>
            </script>
          </material>
        </visual>
        <self_collide>0</self_collide>
        <enable_wind>0</enable_wind>
        <kinematic>0</kinematic>
      </link>
      <pose>0.899026 -0.156325 0 0 -0 0</pose>
    </model>
    <model name='coke_can'>
      <link name='link'>
        <inertial>
          <pose>0 0 0.06 0 -0 0</pose>
          <mass>0.39</mass>
          <inertia>
            <ixx>0.00055575</ixx>
            <ixy>0</ixy>
            <ixz>0</ixz>
            <iyy>0.00055575</iyy>
            <iyz>0</iyz>
            <izz>0.0001755</izz>
          </inertia>
        </inertial>
        <collision name='collision'>
          <pose>0.003937 0.004724 -0.18 0 -0 0</pose>
          <geometry>
            <mesh>
              <uri>model://coke_can/meshes/coke_can.dae</uri>
            </mesh>
          </geometry>
          <surface>
            <friction>
              <ode>
                <mu>1</mu>
                <mu2>1</mu2>
              </ode>
              <torsional>
                <ode/>
              </torsional>
            </friction>
            <contact>
              <ode>
                <kp>1e+07</kp>
                <kd>1</kd>
                <min_depth>0.001</min_depth>
                <max_vel>0.1</max_vel>
              </ode>
            </contact>
            <bounce/>
          </surface>
          <max_contacts>10</max_contacts>
        </collision>
        <visual name='visual'>
          <pose>0.003937 0.004724 -0.18 0 -0 0</pose>
          <geometry>
            <mesh>
              <uri>model://coke_can/meshes/coke_can.dae</uri>
            </mesh>
          </geometry>
        </visual>
        <self_collide>0</self_collide>
        <enable_wind>0</enable_wind>
        <kinematic>0</kinematic>
      </link>
      <pose>0.883149 0.061026 0 0 -0 0</pose>
    </model>
    <model name='bowl'>
      <link name='link'>
        <inertial>
          <pose>0 0 0.0175 0 -0 0</pose>
          <mass>0.1</mass>
          <inertia>
            <ixx>0.000250308</ixx>
            <ixy>0</ixy>
            <ixz>0</ixz>
            <iyy>0.000250308</iyy>
            <iyz>0</iyz>
            <izz>0.0004802</izz>
          </inertia>
        </inertial>
        <collision name='collision'>
          <pose>0 0 0.0175 0 -0 0</pose>
          <geometry>
            <cylinder>
              <radius>0.098</radius>
              <length>0.035</length>
            </cylinder>
          </geometry>
          <max_contacts>10</max_contacts>
          <surface>
            <contact>
              <ode/>
            </contact>
            <bounce/>
            <friction>
              <torsional>
                <ode/>
              </torsional>
              <ode/>
            </friction>
          </surface>
        </collision>
        <visual name='visual'>
          <geometry>
            <mesh>
              <uri>model://bowl/meshes/bowl.dae</uri>
            </mesh>
          </geometry>
        </visual>
        <self_collide>0</self_collide>
        <enable_wind>0</enable_wind>
        <kinematic>0</kinematic>
      </link>
      <pose>0.852744 0.259216 0 0 -0 0</pose>
    </model>
    <model name='plastic_cup'>
      <link name='link'>
        <pose>0 0 0.065 0 -0 0</pose>
        <inertial>
          <mass>0.0599</mass>
          <inertia>
            <ixx>0.000302896</ixx>
            <ixy>0</ixy>
            <ixz>0</ixz>
            <iyy>0.000302896</iyy>
            <iyz>0</iyz>
            <izz>3.28764e-05</izz>
          </inertia>
          <pose>0 0 0 0 -0 0</pose>
        </inertial>
        <collision name='collision'>
          <geometry>
            <mesh>
              <uri>model://plastic_cup/meshes/plastic_cup.dae</uri>
            </mesh>
          </geometry>
          <surface>
            <contact>
              <poissons_ratio>0.35</poissons_ratio>
              <elastic_modulus>3.10264e+09</elastic_modulus>
              <ode>
                <kp>100000</kp>
                <kd>100</kd>
                <max_vel>100</max_vel>
                <min_depth>0.001</min_depth>
              </ode>
            </contact>
            <friction>
              <torsional>
                <coefficient>1</coefficient>
                <use_patch_radius>0</use_patch_radius>
                <surface_radius>0.01</surface_radius>
                <ode/>
              </torsional>
              <ode/>
            </friction>
            <bounce/>
          </surface>
          <max_contacts>10</max_contacts>
        </collision>
        <visual name='visual'>
          <geometry>
            <mesh>
              <uri>model://plastic_cup/meshes/plastic_cup.dae</uri>
            </mesh>
          </geometry>
          <material>
            <script>
              <uri>file://media/materials/scripts/gazebo.material</uri>
              <name>Gazebo/GreyTransparent</name>
            </script>
          </material>
        </visual>
        <self_collide>0</self_collide>
        <enable_wind>0</enable_wind>
        <kinematic>0</kinematic>
      </link>
      <pose>0.791791 0.073774 0 0 -0 0</pose>
    </model>
    <model name='Banana for Scale'>
      <static>1</static>
      <link name='link'>
        <collision name='collision'>
          <pose>0 0 0.12 0 -0 1.5708</pose>
          <geometry>
            <mesh>
              <uri>/home/david/.ignition/fuel/fuel.gazebosim.org/mjcarroll/models/banana for scale/3/meshes/Banana.dae</uri>
            </mesh>
          </geometry>
          <max_contacts>10</max_contacts>
          <surface>
            <contact>
              <ode/>
            </contact>
            <bounce/>
            <friction>
              <torsional>
                <ode/>
              </torsional>
              <ode/>
            </friction>
          </surface>
        </collision>
        <visual name='visual'>
          <pose>0 0 0.12 0 -0 1.5708</pose>
          <geometry>
            <mesh>
              <uri>/home/david/.ignition/fuel/fuel.gazebosim.org/mjcarroll/models/banana for scale/3/meshes/Banana.dae</uri>
            </mesh>
          </geometry>
        </visual>
        <self_collide>0</self_collide>
        <enable_wind>0</enable_wind>
        <kinematic>0</kinematic>
      </link>
      <pose>0.992402 -0.147864 0 0 -0 0</pose>
    </model>
    <model name='orange'>
      <pose>1.00074 0.020017 0.033634 -1.83141 0.386611 2.97317</pose>
      <link name='link'>
        <inertial>
          <inertia>
            <ixx>1.09679e-07</ixx>
            <ixy>-1.79434e-24</ixy>
            <ixz>4.94318e-24</ixz>
            <iyy>1.07389e-07</iyy>
            <iyz>1.64916e-23</iyz>
            <izz>1.06575e-07</izz>
          </inertia>
          <mass>0.000202723</mass>
          <pose>0 0 0 0 -0 0</pose>
        </inertial>
        <collision name='collision'>
          <geometry>
            <mesh>
              <uri>/home/david/.ignition/fuel/fuel.gazebosim.org/gambit/models/orange/3/textured.dae</uri>
            </mesh>
          </geometry>
          <max_contacts>10</max_contacts>
          <surface>
            <contact>
              <ode/>
            </contact>
            <bounce/>
            <friction>
              <torsional>
                <ode/>
              </torsional>
              <ode/>
            </friction>
          </surface>
        </collision>
        <visual name='visual'>
          <geometry>
            <mesh>
              <uri>/home/david/.ignition/fuel/fuel.gazebosim.org/gambit/models/orange/3/textured.dae</uri>
            </mesh>
          </geometry>
        </visual>
        <self_collide>0</self_collide>
        <enable_wind>0</enable_wind>
        <kinematic>0</kinematic>
      </link>
    </model>
  </world>
</sdf>
